Workbook
Name Type: #REF!
Name Type: #REF!
Name Type: #REF!
Name Type: #REF!

Sheet Parameters
C4: Assumptions
C5: Procurement of Bikes | D5: 60
C6: Price per Bike | D6: 1300000
C7: Bike Assembly Per Bike | D7: 7000
C10: Daily Rental per Bike | D10: 6000
C12: Operating Hours | D12: 15 hours
C13: Operating Days in a week | D13: 7
C14: Operating Days in a month | D14: 30
C15: Operating Days in a year | D15: 365
C17: Maintenance | D17: Once a month
C18: Maintenance Price | D18: 60000
C21: NO. of Swap Stations | D21: 8
C26: Annual Growth Exchange Rate | D26: 0.1
C27: Investment Period | D27: 5
C29: Exchange Rate | D29: 1600 | E29: 10% Annual Depreciation

Sheet Exchang Rate Growth
C3: Exchange Rate | D3: Year 1 | E3: Year 2 | F3: Year 3 | G3: Year 4 | H3: Year 5
C4: Number of Tricycles | D4: NGN | E4: NGN | F4: NGN | G4: NGN | H4: NGN
C5: Depreciation Factor | E5: 1.1 | F5: 1.1 | G5: 1.1 | H5: 1.1
C6: Exchange Rate | D6: =Parameters!D29 -> 1600 | E6: =D6*E5 -> 1760 | F6: =E6*F5 -> 1936 | G6: =F6*G5 -> 2129.6 | H6: =G6*H5 -> 2342.56
C12: Inflation Rate | D12: 0.05 | E12: 0.05 | F12: 0.05 | G12: 0.05 | H12: 0.05

Sheet CAPITAL INFLOW
B1: CAPITAL BUDGET
B2: PERAMARE MEDICAL | C2: [YEAR]
B3: 1st JANUARY | C3: ESTIMATE
B5: CAPITAL EXPENDITURE
B6: Purchase Of Equpments | C6: =CAPEX!D63 -> 1.6690477e+08
B7: Purchase Of Motor Vehicle | C7: 0
B8: Purchase Of Building | C8: 0
B9: Energy and Power | C9: 6000000
B10: Construction And Renovation | C10: 0
B11: Purchase Of Office Supplies | C11: 0
B12: Furnitures and Fittings | C12: =CAPEX!#REF! -> #REF!
B13: Purchase Of Land | C13: 0
B14: Purchase Of Machinery | C14: =CAPEX!D7 -> 68647500
B15: TOTAL CAPITAL EXPENDITURE | C15: =SUM(C6:C14) -> #REF!
B17: EXPENDITURE
B18: Training | C18: 0
B19: Subscription | C19: 0
B20: Office expense | C20: ='INCOME STATEMENT - 3 YEARS'!D45 -> 420000
B21: Licensing | C21: 0
B22: Utilities | C22: 0
B23: Office Equipment | C23: 0
B24: Landscaping | C24: 0
B25: Agent fees | C25: 0
B26: Legal fees | C26: 0
B27: Consultancy fees | C27: 0
B28: Salaries & Wages | C28: ='INCOME STATEMENT - 3 YEARS'!D36 -> 14760000
B29: Rent | C29: ='INCOME STATEMENT - 3 YEARS'!D39 -> 1000000
B30: Mortgage | C30: 0
B31: Marketing, and Promotions | C31: 1000000
B32: Insurance | C32: 0
B33: Maintenance and Repairs | C33: ='INCOME STATEMENT - 3 YEARS'!D44 -> 3600000
B34: TOTAL EXPENDITURE | C34: =SUM(C18:C33) -> 20780000

Sheet INCOME STATEMENT
B1: PROJECTED INCOME STATEMENT
B2: COMPANY NAME
B3: PERAMARE TRANSPORT COMPANY LTD
B5: TIME PERIOD REPRESENTED
B6: 1 Year
C8: TREND | D8: JANUARY | E8: FEBRUARY | F8: MARCH | G8: APRIL | H8: MAY | I8: JUNE | J8: JULY | K8: AUGUST | L8: SEPTEMBER | M8: OCTOBER | N8: NOVEMBER | O8: DECEMBER | Q8: YTD
D9: NGN | E9: NGN | F9: NGN | G9: NGN | H9: NGN | I9: NGN | J9: NGN | K9: NGN | L9: NGN | M9: NGN | N9: NGN | O9: NGN | Q9: NGN
B10: REVENUE | D10: =D19 -> 11160000 | E10: =E19 -> 11160000 | F10: =F19 -> 11160000 | G10: =G19 -> 11160000 | H10: =H19 -> 11160000 | I10: =I19 -> 11160000 | J10: =J19 -> 11160000 | K10: =K19 -> 11160000 | ... O10: =O19 -> 11160000 | Q10: =SUM(D10:O10) -> 133920000
B11: TOTAL EXPENSES | D11: =D48 -> 2.412486e+08 | E11: =E48 -> 1676333.3 | F11: =F48 -> 1676333.3 | G11: =G48 -> 1676333.3 | H11: =H48 -> 1676333.3 | I11: =I48 -> 1676333.3 | J11: =J48 -> 1676333.3 | K11: =K48 -> 1676333.3 | ... O11: =O48 -> 1651333.3 | Q11: =SUM(D11:O11) -> 2.5963827e+08
B12: PROFIT / LOSS | D12: =D10-D11 -> -2.300886e+08 | E12: =E10-E11 -> 9483666.7 | F12: =F10-F11 -> 9483666.7 | G12: =G10-G11 -> 9483666.7 | H12: =H10-H11 -> 9483666.7 | I12: =I10-I11 -> 9483666.7 | J12: =J10-J11 -> 9483666.7 | K12: =K10-K11 -> 9483666.7 | ... O12: =O10-O11 -> 9508666.7 | Q12: =Q10-Q11 -> -1.2571827e+08
B15: REVENUE | C15: TREND | D15: JANUARY | E15: FEBRUARY | F15: MARCH | G15: APRIL | H15: MAY | I15: JUNE | J15: JULY | K15: AUGUST | L15: SEPTEMBER | M15: OCTOBER | N15: NOVEMBER | O15: DECEMBER | Q15: YTD
D16: NGN | E16: NGN | F16: NGN | G16: NGN | H16: NGN | I16: NGN | J16: NGN | K16: NGN | L16: NGN | M16: NGN | N16: NGN | O16: NGN | Q16: NGN
B17: Income from Bike Rental | D17: ='REVENUE GENERATION'!N4 -> 11160000 | E17: ='REVENUE GENERATION'!N4 -> 11160000 | F17: ='REVENUE GENERATION'!N4 -> 11160000 | G17: ='REVENUE GENERATION'!N4 -> 11160000 | H17: =G17 -> 11160000 | I17: =H17 -> 11160000 | J17: =I17 -> 11160000 | K17: =J17 -> 11160000 | L17: =K17 -> 11160000 | M17: =L17 -> 11160000 | N17: =M17 -> 11160000 | O17: =N17 -> 11160000 | Q17: =D17+E17+F17+G17+H17+I17+J17+K17+L17+M17+N17+O17 -> 133920000
B18: Income from Bike Sales | D18: ='REVENUE GENERATION'!N5 -> 0 | E18: ='REVENUE GENERATION'!N5 -> 0 | F18: ='REVENUE GENERATION'!N5 -> 0 | G18: ='REVENUE GENERATION'!N5 -> 0 | H18: =G18 -> 0 | I18: =H18 -> 0 | J18: =I18 -> 0 | K18: =J18 -> 0 | L18: =K18 -> 0 | M18: =L18 -> 0 | N18: =M18 -> 0 | O18: =N18 -> 0 | Q18: =D18+E18+F18+G18+H18+I18+J18+K18+L18+M18+N18+O18 -> 0
B19: TOTAL REVENUE | D19: =SUM(D17:D18) -> 11160000 | E19: =SUM(E17:E18) -> 11160000 | F19: =SUM(F17:F18) -> 11160000 | G19: =SUM(G17:G18) -> 11160000 | H19: =SUM(H17:H18) -> 11160000 | I19: =SUM(I17:I18) -> 11160000 | J19: =SUM(J17:J18) -> 11160000 | K19: =SUM(K17:K18) -> 11160000 | ... O19: =SUM(O17:O18) -> 11160000 | Q19: =SUM(Q17:Q18) -> 133920000
B21: COST OF SALES | C21: TREND | D21: JANUARY | E21: FEBRUARY | F21: MARCH | G21: APRIL | H21: MAY | I21: JUNE | J21: JULY | K21: AUGUST | L21: SEPTEMBER | M21: OCTOBER | N21: NOVEMBER | O21: DECEMBER | Q21: YTD
D22: NGN | E22: NGN | F22: NGN | G22: NGN | H22: NGN | I22: NGN | J22: NGN | K22: NGN | L22: NGN | M22: NGN | N22: NGN | O22: NGN | Q22: NGN
B23: Less Sales Returns | D23: 0 | E23: 0 | F23: 0 | G23: 0 | H23: 0 | I23: 0 | J23: 0 | K23: 0 | L23: 0 | M23: 0 | N23: 0 | O23: 0 | Q23: =SUM(D23:O23) -> 0
B24: Less Sales Discounts | D24: 0 | E24: 0 | F24: 0 | G24: 0 | H24: 0 | I24: 0 | J24: 0 | K24: 0 | L24: 0 | M24: 0 | N24: 0 | O24: 0 | Q24: =SUM(D24:O24) -> 0
B25: Less Cost of Goods Sold | D25: 0 | E25: 0 | F25: 0 | G25: 0 | H25: 0 | I25: 0 | J25: 0 | K25: 0 | L25: 0 | M25: 0 | N25: 0 | O25: 0 | Q25: =SUM(D25:O25) -> 0
B26: COST OF SALES | D26: 0 | E26: 0 | F26: 0 | G26: 0 | H26: 0 | I26: 0 | J26: 0 | K26: 0 | L26: 0 | M26: 0 | N26: 0 | O26: 0 | Q26: =SUM(D26:O26) -> 0
B28: GROSS PROFIT | REVENUE - COST OF SALES | D28: =D19-D26 -> 11160000 | E28: =E19-E26 -> 11160000 | F28: =F19-F26 -> 11160000 | G28: =G19-G26 -> 11160000 | H28: =H19-H26 -> 11160000 | I28: =I19-I26 -> 11160000 | J28: =J19-J26 -> 11160000 | K28: =K19-K26 -> 11160000 | ... O28: =O19-O26 -> 11160000 | Q28: =Q19-Q26 -> 133920000
B30: EXPENSES
B31: ADMINISTRATIVE EXPENSE | C31: TREND | D31: JANUARY | E31: FEBRUARY | F31: MARCH | G31: APRIL | H31: MAY | I31: JUNE | J31: JULY | K31: AUGUST | L31: SEPTEMBER | M31: OCTOBER | N31: NOVEMBER | O31: DECEMBER | Q31: YTD
D32: NGN | E32: NGN | F32: NGN | G32: NGN | H32: NGN | I32: NGN | J32: NGN | K32: NGN | L32: NGN | M32: NGN | N32: NGN | O32: NGN | Q32: NGN
B33: Power and Energy | D33: =CAPEX!D29 -> 6000000 | E33: 0 | F33: =E33 -> 0 | G33: =F33 -> 0 | H33: =G33 -> 0 | I33: =H33 -> 0 | J33: =I33 -> 0 | K33: =J33 -> 0 | L33: =K33 -> 0 | M33: =L33 -> 0 | ... O33: =N33 -> 0 | Q33: =D33+E33+F33+G33+H33+I33+J33+K33+L33+M33+N33+O33 -> 6000000
B34: Office Equipments | D34: =CAPEX!D63 -> 1.6690477e+08 | E34: 0 | F34: =E34 -> 0 | G34: =F34 -> 0 | H34: =G34 -> 0 | I34: =H34 -> 0 | J34: =I34 -> 0 | K34: =J34 -> 0 | L34: =K34 -> 0 | M34: =L34 -> 0 | ... O34: =N34 -> 0 | Q34: =D34+E34+F34+G34+H34+I34+J34+K34+L34+M34+N34+O34 -> 1.6690477e+08
B35: Salaries & Wages | D35: =OPEX!H22 -> 1230000 | E35: =D35 -> 1230000 | F35: =E35 -> 1230000 | G35: =F35 -> 1230000 | H35: =G35 -> 1230000 | I35: =H35 -> 1230000 | J35: =I35 -> 1230000 | K35: =J35 -> 1230000 | L35: =K35 -> 1230000 | ... O35: =N35 -> 1230000 | Q35: =D35+E35+F35+G35+H35+I35+J35+K35+L35+M35+N35+O35 -> 14760000
B36: Staff Welfare, Medicals and Entertainment | D36: 0 | E36: =D36 -> 0 | F36: =E36 -> 0 | G36: =F36 -> 0 | H36: =G36 -> 0 | I36: =H36 -> 0 | J36: =I36 -> 0 | K36: =J36 -> 0 | L36: =K36 -> 0 | ... O36: =N36 -> 0 | Q36: =D36+E36+F36+G36+H36+I36+J36+K36+L36+M36+N36+O36 -> 0
B37: Training and Development | D37: 0 | E37: =D37 -> 0 | F37: =E37 -> 0 | G37: =F37 -> 0 | H37: =G37 -> 0 | I37: =H37 -> 0 | J37: =I37 -> 0 | K37: =J37 -> 0 | L37: =K37 -> 0 | ... O37: =N37 -> 0 | Q37: =D37+E37+F37+G37+H37+I37+J37+K37+L37+M37+N37+O37 -> 0
B38: Rent and Mortgage | D38: =CAPEX!D20 -> 1000000 | E38: 0 | F38: =E38 -> 0 | G38: =F38 -> 0 | H38: =G38 -> 0 | I38: =H38 -> 0 | J38: =I38 -> 0 | K38: =J38 -> 0 | L38: =K38 -> 0 | M38: =L38 -> 0 | ... O38: =N38 -> 0 | Q38: =D38+E38+F38+G38+H38+I38+J38+K38+L38+M38+N38+O38 -> 1000000
B39: Office Supplies | D39: 0 | E39: =D39 -> 0 | F39: =E39 -> 0 | G39: =F39 -> 0 | H39: =G39 -> 0 | I39: =H39 -> 0 | J39: =I39 -> 0 | K39: =J39 -> 0 | L39: =K39 -> 0 | ... O39: =N39 -> 0 | Q39: =D39+E39+F39+G39+H39+I39+J39+K39+L39+M39+N39+O39 -> 0
B40: Utilities | D40: 0 | E40: =D40 -> 0 | F40: =E40 -> 0 | G40: =F40 -> 0 | H40: =G40 -> 0 | I40: =H40 -> 0 | J40: =I40 -> 0 | K40: =J40 -> 0 | L40: =K40 -> 0 | ... O40: =N40 -> 0 | Q40: =D40+E40+F40+G40+H40+I40+J40+K40+L40+M40+N40+O40 -> 0
B41: Advertising, Marketing, and Promotions | D41: ='CAPITAL INFLOW'!C31/12 -> 83333.333 | E41: =D41 -> 83333.333 | F41: =E41 -> 83333.333 | G41: =F41 -> 83333.333 | H41: =G41 -> 83333.333 | I41: =H41 -> 83333.333 | J41: =I41 -> 83333.333 | K41: =J41 -> 83333.333 | L41: =K41 -> 83333.333 | ... O41: =N41 -> 83333.333 | Q41: =D41+E41+F41+G41+H41+I41+J41+K41+L41+M41+N41+O41 -> 1000000
B42: Purchase of Machinery | D42: =CAPEX!D7 -> 68647500 | E42: 0 | F42: =E42 -> 0 | G42: =F42 -> 0 | H42: =G42 -> 0 | I42: =H42 -> 0 | J42: =I42 -> 0 | K42: =J42 -> 0 | L42: =K42 -> 0 | M42: =L42 -> 0 | ... O42: =N42 -> 0 | Q42: =D42+E42+F42+G42+H42+I42+J42+K42+L42+M42+N42+O42 -> 68647500
B43: Repairs and Maintainance | D43: =OPEX!H40/12 -> 300000 | E43: =D43 -> 300000 | F43: =E43 -> 300000 | G43: =F43 -> 300000 | H43: =G43 -> 300000 | I43: =H43 -> 300000 | J43: =I43 -> 300000 | K43: =J43 -> 300000 | L43: =K43 -> 300000 | ... O43: =N43 -> 300000 | Q43: =D43+E43+F43+G43+H43+I43+J43+K43+L43+M43+N43+O43 -> 3600000
B44: Bike Assembly | D44: =CAPEX!G13 -> 420000 | E44: 0 | F44: =E44 -> 0 | G44: =F44 -> 0 | H44: =G44 -> 0 | I44: =H44 -> 0 | J44: =I44 -> 0 | K44: =J44 -> 0 | L44: =K44 -> 0 | M44: =L44 -> 0 | ... O44: =N44 -> 0 | Q44: =D44+E44+F44+G44+H44+I44+J44+K44+L44+M44+N44+O44 -> 420000
B45: Internet and communication | D45: 38000 | E45: =D45 -> 38000 | F45: =E45 -> 38000 | G45: =F45 -> 38000 | H45: =G45 -> 38000 | I45: =H45 -> 38000 | J45: =I45 -> 38000 | K45: =J45 -> 38000 | L45: =K45 -> 38000 | ... O45: =N45 -> 38000 | Q45: =D45+E45+F45+G45+H45+I45+J45+K45+L45+M45+N45+O45 -> 456000
B46: Shipping and Clearance | D46: =CAPEX!D83 -> 2600000 | E46: 0 | F46: =E46 -> 0 | G46: =F46 -> 0 | H46: =G46 -> 0 | I46: =H46 -> 0 | J46: =I46 -> 0 | K46: =J46 -> 0 | L46: =K46 -> 0 | M46: =L46 -> 0 | ... O46: =N46 -> 0 | Q46: =D46+E46+F46+G46+H46+I46+J46+K46+L46+M46+N46+O46 -> 2600000
B47: Others | D47: 25000 | E47: =D47 -> 25000 | F47: =E47 -> 25000 | G47: =F47 -> 25000 | H47: =G47 -> 25000 | I47: =H47 -> 25000 | J47: =I47 -> 25000 | K47: =J47 -> 25000 | L47: =K47 -> 25000 | M47: =L47 -> 25000 | N47: 0 | O47: =N47 -> 0 | Q47: =D47+E47+F47+G47+H47+I47+J47+K47+L47+M47+N47+O47 -> 250000
...

Sheet INCOME STATEMENT - 3 YEARS
B1: PROJECTED INCOME STATEMENT
B2: COMPANY NAME
B3: PERAMARE TRANSPORT COMAPANY LTD
B5: TIME PERIOD REPRESENTED
B6: 3 Years
C9: TREND | D9: YEAR 1 | E9: YEAR 2 | F9: YEAR 3 | H9: YTD
D10: NGN | E10: NGN | F10: NGN | H10: NGN
B11: REVENUE | D11: =D20 -> 131400000 | E11: =E20 -> 131400000 | F11: =F20 -> 131400000 | H11: =D11+E11+F11 -> 394200000
B12: TOTAL EXPENSES | D12: =D49+D60 -> 2.7854875e+08 | E12: =E49+E60 -> 38176477 | F12: =F49+F60 -> 38176477 | H12: =D12+E12+F12 -> 3.549017e+08
B13: PROFIT / LOSS | D13: =D11-D12 -> -1.4714875e+08 | E13: =E11-E12 -> 93223523 | F13: =F11-F12 -> 93223523 | H13: =D13+E13+F13 -> 39298298
B16: REVENUE | C16: TREND | D16: YEAR 1 | E16: YEAR 2 | F16: YEAR 3 | H16: YTD
D17: NGN | E17: NGN | F17: NGN | H17: NGN
B18: ='INCOME STATEMENT'!B17 -> Income from Bike Rental | D18: ='REVENUE GENERATION'!O4 -> 131400000 | E18: =D18 -> 131400000 | F18: =E18 -> 131400000 | H18: =D18+E18+F18 -> 394200000
B19: ='INCOME STATEMENT'!B18 -> Income from Bike Sales | D19: ='REVENUE GENERATION'!O5 -> 0 | E19: =D19 -> 0 | F19: =E19 -> 0 | H19: =D19+E19+F19 -> 0
B20: TOTAL REVENUE | D20: =SUM(D18:D19) -> 131400000 | E20: =SUM(E18:E19) -> 131400000 | F20: =SUM(F18:F19) -> 131400000 | H20: =SUM(H18:H19) -> 394200000
B22: COST OF SALES | C22: TREND | D22: JANUARY | E22: FEBRUARY | F22: MARCH | H22: YTD
D23: NGN | E23: NGN | F23: NGN | H23: NGN
B24: Less Sales Returns | D24: 0 | E24: 0 | F24: 0 | H24: =D24+E24+F24 -> 0
B25: Less Sales Discounts | D25: 0 | E25: 0 | F25: 0 | H25: =D25+E25+F25 -> 0
B26: Less Cost of Goods Sold | D26: 0 | E26: 0 | F26: 0 | H26: =D26+E26+F26 -> 0
B27: COST OF SALES | D27: 0 | E27: 0 | F27: 0 | H27: =SUM(H24:H26) -> 0
B29: GROSS PROFIT | REVENUE - COST OF SALES | D29: =D20-D27 -> 131400000 | E29: =E20-E27 -> 131400000 | F29: =F20-F27 -> 131400000 | H29: =H20-H27 -> 394200000
B31: EXPENSES
B32: ADMINISTRATIVE EXPENSE | C32: TREND | D32: YEAR 1 | E32: YEAR 2 | F32: YEAR 3 | H32: YTD
D33: NGN | E33: NGN | F33: NGN | H33: NGN
B34: ='INCOME STATEMENT'!B33 -> Power and Energy | D34: ='INCOME STATEMENT'!Q33 -> 6000000 | E34: 0 | F34: =E34 -> 0 | H34: =D34+E34+F34 -> 6000000
B35: ='INCOME STATEMENT'!B34 -> Office Equipments | D35: ='INCOME STATEMENT'!Q34 -> 1.6690477e+08 | E35: 0 | F35: 0 | H35: =D35+E35+F35 -> 1.6690477e+08
B36: ='INCOME STATEMENT'!B35 -> Salaries & Wages | D36: ='INCOME STATEMENT'!Q35 -> 14760000 | E36: =D36 -> 14760000 | F36: =E36 -> 14760000 | H36: =D36+E36+F36 -> 44280000
B37: ='INCOME STATEMENT'!B36 -> Staff Welfare, Medicals and Entertainment | D37: ='INCOME STATEMENT'!Q36 -> 0 | E37: =D37 -> 0 | F37: =E37 -> 0 | H37: =D37+E37+F37 -> 0
B38: ='INCOME STATEMENT'!B37 -> Training and Development | D38: ='INCOME STATEMENT'!Q37 -> 0 | E38: =D38 -> 0 | F38: =E38 -> 0 | H38: =D38+E38+F38 -> 0
B39: ='INCOME STATEMENT'!B38 -> Rent and Mortgage | D39: ='INCOME STATEMENT'!Q38 -> 1000000 | E39: =D39 -> 1000000 | F39: =E39 -> 1000000 | H39: =D39+E39+F39 -> 3000000
B40: ='INCOME STATEMENT'!B39 -> Office Supplies | D40: ='INCOME STATEMENT'!Q39 -> 0 | E40: =D40 -> 0 | F40: =E40 -> 0 | H40: =D40+E40+F40 -> 0
B41: ='INCOME STATEMENT'!B40 -> Utilities | D41: ='INCOME STATEMENT'!Q40 -> 0 | E41: =D41 -> 0 | F41: =E41 -> 0 | H41: =D41+E41+F41 -> 0
B42: ='INCOME STATEMENT'!B41 -> Advertising, Marketing, and Promotions | D42: ='INCOME STATEMENT'!Q41 -> 1000000 | E42: =D42 -> 1000000 | F42: =E42 -> 1000000 | H42: =D42+E42+F42 -> 3000000
B43: ='INCOME STATEMENT'!B42 -> Purchase of Machinery | D43: ='INCOME STATEMENT'!Q42 -> 68647500 | E43: 0 | F43: 0 | H43: =D43+E43+F43 -> 68647500
B44: ='INCOME STATEMENT'!B43 -> Repairs and Maintainance | D44: ='INCOME STATEMENT'!Q43 -> 3600000 | E44: =D44 -> 3600000 | F44: =E44 -> 3600000 | H44: =D44+E44+F44 -> 10800000
B45: ='INCOME STATEMENT'!B44 -> Bike Assembly | D45: ='INCOME STATEMENT'!Q44 -> 420000 | E45: =D45 -> 420000 | F45: =E45 -> 420000 | H45: =D45+E45+F45 -> 1260000
B46: ='INCOME STATEMENT'!B45 -> Internet and communication | D46: ='INCOME STATEMENT'!Q45 -> 456000 | E46: =D46 -> 456000 | F46: =E46 -> 456000 | H46: =D46+E46+F46 -> 1368000
B47: ='INCOME STATEMENT'!B46 -> Shipping and Clearance | D47: ='INCOME STATEMENT'!Q46 -> 2600000 | E47: 0 | F47: =E47 -> 0 | H47: =D47+E47+F47 -> 2600000
B48: ='INCOME STATEMENT'!B47 -> Others | D48: ='INCOME STATEMENT'!Q47 -> 250000 | E48: =D48 -> 250000 | F48: =E48 -> 250000 | H48: =D48+E48+F48 -> 750000
...

Sheet CASH FLOW STATEMENT
B1: PROJECTED CASH FLOW STATEMENT
B2: PERAMARE TRANSPORT | C2: YEAR 1 | D2: YEAR 2 | E2: YEAR 3 | G2: TOTAL
C3: ESTIMATE | D3: ESTIMATE | E3: ESTIMATE | G3: ESTIMATE
C4: NGN | D4: NGN | E4: NGN | G4: NGN
B7: CASH INFLOW | C7: =0 -> 0 | D7: =0 -> 0 | E7: =0 -> 0
B9: ='REVENUE GENERATION'!B4 -> Bike Rental | C9: ='REVENUE GENERATION'!O4 -> 131400000 | D9: =C9 -> 131400000 | E9: =D9 -> 131400000 | G9: =SUM(C9:E9) -> 394200000
B10: ='REVENUE GENERATION'!B5 -> Battery Swap | C10: ='REVENUE GENERATION'!O5 -> 0 | D10: =C10 -> 0 | E10: =D10 -> 0 | G10: =SUM(C10:E10) -> 0
B11: TOTAL CASH INFLOWS | C11: =SUM(C9:C10) -> 131400000 | D11: =SUM(D9:D10) -> 131400000 | E11: =SUM(E9:E10) -> 131400000 | G11: =SUM(C11:E11) -> 394200000
B12: INVESTING ACTIVITIES | C12: 0 | D12: 0 | E12: 0 | G12: =SUM(C12:E12) -> 0
B13: Power and Energy | C13: ='INCOME STATEMENT - 3 YEARS'!D34 -> 6000000 | D13: ='INCOME STATEMENT - 3 YEARS'!E34 -> 0 | E13: ='INCOME STATEMENT - 3 YEARS'!F34 -> 0 | G13: =SUM(C13:E13) -> 6000000
B14: ='INCOME STATEMENT - 3 YEARS'!B35 -> Office Equipments | C14: ='INCOME STATEMENT - 3 YEARS'!D35 -> 1.6690477e+08 | D14: ='INCOME STATEMENT - 3 YEARS'!E35 -> 0 | E14: ='INCOME STATEMENT - 3 YEARS'!F35 -> 0 | G14: =SUM(C14:E14) -> 1.6690477e+08
B15: ='INCOME STATEMENT - 3 YEARS'!B43 -> Purchase of Machinery | C15: ='INCOME STATEMENT - 3 YEARS'!D43 -> 68647500 | D15: ='INCOME STATEMENT - 3 YEARS'!E43 -> 0 | E15: ='INCOME STATEMENT - 3 YEARS'!F43 -> 0 | G15: =SUM(C15:E15) -> 68647500
B16: GOVERNMENT GRANT | C16: 0 | D16: 0 | E16: 0 | G16: =SUM(C16:E16) -> 0
B17: TOTAL INVESTING ACTIVITIES | C17: =SUM(C13:C16) -> 2.4155227e+08 | D17: =SUM(D13:D16) -> 0 | E17: =SUM(E13:E16) -> 0 | G17: =SUM(C17:E17) -> 2.4155227e+08
B18: OPERATING ACTIVITIES | C18: 0 | D18: 0 | E18: 0 | G18: =SUM(C18:E18) -> 0
B19: ='INCOME STATEMENT'!B35 -> Salaries & Wages | C19: ='INCOME STATEMENT - 3 YEARS'!D36 -> 14760000 | D19: =C19 -> 14760000 | E19: =D19 -> 14760000 | G19: =SUM(C19:E19) -> 44280000
B20: ='INCOME STATEMENT'!B36 -> Staff Welfare, Medicals and Entertainment | C20: ='INCOME STATEMENT'!D36 -> 0 | D20: =C20 -> 0 | E20: =D20 -> 0 | G20: =SUM(C20:E20) -> 0
B21: ='INCOME STATEMENT'!B37 -> Training and Development | C21: ='INCOME STATEMENT'!D37 -> 0 | D21: =C21 -> 0 | E21: =D21 -> 0 | G21: =SUM(C21:E21) -> 0
B22: ='INCOME STATEMENT'!B38 -> Rent and Mortgage | C22: ='INCOME STATEMENT'!D38 -> 1000000 | D22: =C22 -> 1000000 | E22: =D22 -> 1000000 | G22: =SUM(C22:E22) -> 3000000
B23: ='INCOME STATEMENT'!B39 -> Office Supplies | C23: ='INCOME STATEMENT'!D39 -> 0 | D23: =C23 -> 0 | E23: =D23 -> 0 | G23: =SUM(C23:E23) -> 0
B24: ='INCOME STATEMENT'!B40 -> Utilities | C24: ='INCOME STATEMENT'!D40 -> 0 | D24: =C24 -> 0 | E24: =D24 -> 0 | G24: =SUM(C24:E24) -> 0
B25: ='INCOME STATEMENT'!B41 -> Advertising, Marketing, and Promotions | C25: ='INCOME STATEMENT - 3 YEARS'!D42 -> 1000000 | D25: ='INCOME STATEMENT - 3 YEARS'!E42 -> 1000000 | E25: ='INCOME STATEMENT - 3 YEARS'!F42 -> 1000000 | G25: =SUM(C25:E25) -> 3000000
B26: ='INCOME STATEMENT'!B43 -> Repairs and Maintainance | C26: ='INCOME STATEMENT - 3 YEARS'!D44 -> 3600000 | D26: ='INCOME STATEMENT - 3 YEARS'!E44 -> 3600000 | E26: ='INCOME STATEMENT - 3 YEARS'!F44 -> 3600000 | G26: =SUM(C26:E26) -> 10800000
B27: ='INCOME STATEMENT'!B44 -> Bike Assembly | C27: ='INCOME STATEMENT - 3 YEARS'!D45 -> 420000 | D27: 0 | E27: =D27 -> 0 | G27: =SUM(C27:E27) -> 420000
B28: ='INCOME STATEMENT'!B45 -> Internet and communication | C28: ='INCOME STATEMENT'!D45 -> 38000 | D28: =C28 -> 38000 | E28: =D28 -> 38000 | G28: =SUM(C28:E28) -> 114000
B29: ='INCOME STATEMENT'!B46 -> Shipping and Clearance | C29: ='INCOME STATEMENT'!D46 -> 2600000 | D29: 0 | E29: =D29 -> 0 | G29: =SUM(C29:E29) -> 2600000 | I29: 0
B30: ='INCOME STATEMENT'!B47 -> Others | C30: ='INCOME STATEMENT'!D47 -> 25000 | D30: =C30 -> 25000 | E30: =D30 -> 25000 | G30: =SUM(C30:E30) -> 75000
B31: ='INCOME STATEMENT'!B53 -> Depreciation and Amortization | C31: 0 | D31: =C31 -> 0 | E31: =D31 -> 0 | G31: =SUM(C31:E31) -> 0
B32: ='INCOME STATEMENT'!B54 -> Licensing | C32: ='INCOME STATEMENT'!D54 -> 2220000 | D32: 0 | E32: =D32 -> 0 | G32: =SUM(C32:E32) -> 2220000
B33: ='INCOME STATEMENT'!B57 -> Insurance | C33: ='INCOME STATEMENT'!D57 -> 0 | D33: =C33 -> 0 | E33: =D33 -> 0 | G33: =SUM(C33:E33) -> 0
B34: NET CASH INFLOW AFTER OPERATING ACTIVITIES | C34: =SUM(C19:C33) -> 25663000 | D34: =SUM(D19:D33) -> 20423000 | E34: =SUM(E19:E33) -> 20423000 | G34: =SUM(C34:E34) -> 66509000
B35: FINANCING OPERATIONS | C35: 0 | D35: =C35 -> 0 | E35: =D35 -> 0 | G35: =SUM(C35:E35) -> 0
C36: 0 | D36: =C36 -> 0 | E36: =D36 -> 0 | G36: =SUM(C36:E36) -> 0
B37: STAMP DUTY | C37: =C34*1% -> 256630 | D37: =D34*1% -> 204230 | E37: =E34*1% -> 204230 | G37: =SUM(C37:E37) -> 665090
B38: TAX | C38: ='INCOME STATEMENT - 3 YEARS'!D73 -> 0 | D38: ='INCOME STATEMENT - 3 YEARS'!E73 -> 0 | E38: ='INCOME STATEMENT - 3 YEARS'!F73 -> 27967057 | G38: =SUM(C38:E38) -> 27967057
B39: DIVIDEND PAID | C39: 0 | D39: =C39 -> 0 | E39: =D39 -> 0 | G39: =SUM(C39:E39) -> 0
B40: ORDINARY SHARES | C40: 0 | D40: =C40 -> 0 | E40: =D40 -> 0 | G40: =SUM(C40:E40) -> 0
B41: BANK CHARGES | C41: =(SUM(C34:C39)/1000*2) -> 51839.26 | D41: =(SUM(D34:D39)/1000*2) -> 41254.46 | E41: =(SUM(E34:E39)/1000*2) -> 97188.574 | G41: =SUM(C41:E41) -> 190282.29
B42: NET CASH INFLOW AFTER FINANCING OPERATIONS | C42: =SUM(C37:C41) -> 308469.26 | D42: =SUM(D37:D41) -> 245484.46 | E42: =SUM(E37:E41) -> 28268475 | G42: =SUM(C42:E42) -> 28822429
C43: 0 | D43: 0 | E43: 0 | G43: =SUM(C43:E43) -> 0
...

Sheet STATEMENT OF FINANCIAL POSITION
B2: PERAMARE TRANSPORT | D2: PROJECTED STATEMENT OF FINANCIAL POSITION
B4: ASSETS | D4: YEAR 1 | E4: YEAR 2 | F4: YEAR 3 | H4: TOTAL
B5: NON-CURRENT ASSETS (LONG-TERM) ASSETS | D5: 0
B6: Long-Term Investments | D6: =SUM('CASH FLOW STATEMENT'!C17)+1089522.29 -> 2.4264179e+08 | E6: =SUM('CASH FLOW STATEMENT'!D17) -> 0 | F6: =SUM('CASH FLOW STATEMENT'!E17) -> 0 | H6: =SUM(D6:F6) -> 2.4264179e+08
B7: Property, Plant, and Equipment | D7: ='CASH FLOW STATEMENT'!C14 -> 1.6690477e+08 | E7: ='CASH FLOW STATEMENT'!D14 -> 0 | F7: ='CASH FLOW STATEMENT'!E14 -> 0 | H7: =SUM(D7:F7) -> 1.6690477e+08
B8: (Less Accumulated Depreciation) | D8: ='INCOME STATEMENT - 3 YEARS'!D54 -> 16690477 | E8: ='INCOME STATEMENT - 3 YEARS'!E54 -> 16690477 | F8: ='INCOME STATEMENT - 3 YEARS'!F54 -> 16690477 | H8: =SUM(D8:F8) -> 50071431
B9: Intangible Assets | D9: 0 | E9: 0 | F9: 0
B10: TOTAL NON-CURRENT ASSETS | D10: =SUM(D5:D9) -> 4.2623704e+08 | E10: =SUM(E6:E9) -> 16690477 | F10: =SUM(F6:F9) -> 16690477 | H10: =SUM(H6:H9) -> 4.59618e+08
B11: CURRENT ASSETS
B12: Cash | D12: 0 | E12: ='CASH FLOW STATEMENT'!D44 -> 1.1122248e+08 | F12: ='CASH FLOW STATEMENT'!E44 -> 1.3924548e+08 | H12: =SUM(D12:F12) -> 2.5046796e+08
B13: Accounts Receivable | D13: =0 -> 0 | E13: 0 | F13: 0 | H13: =SUM(D13:F13) -> 0
B14: Inventory | D14: =CAPEX!D7 -> 68647500 | E14: 0 | F14: ='INCOME STATEMENT - 3 YEARS'!F43 -> 0 | H14: =SUM(D14:F14) -> 68647500
B15: Prepaid Expenses | D15: 0 | E15: 0 | F15: 0 | H15: =SUM(D15:F15) -> 0
B16: Short-Term Investments | D16: 0 | E16: 0 | F16: 0 | H16: =SUM(D16:F16) -> 0
B17: Deferred Income Tax | D17: ='CASH FLOW STATEMENT'!C38 -> 0 | E17: ='CASH FLOW STATEMENT'!D38 -> 0 | F17: ='CASH FLOW STATEMENT'!E38 -> 27967057 | H17: =SUM(D17:F17) -> 27967057
B18: Others | D18: 0 | E18: 0 | F18: 0 | H18: =SUM(D18:F18) -> 0
B19: TOTAL CURRENT ASSETS | D19: =SUM(D12:D18) -> 68647500 | E19: =SUM(E12:E18) -> 1.1122248e+08 | F19: =SUM(F12:F18) -> 1.6721253e+08 | H19: =SUM(H12:H18) -> 3.4708252e+08
B21: TOTAL ASSETS | D21: =SUM(D10,D19) -> 4.9488454e+08 | E21: =SUM(E10,E19) -> 1.2791296e+08 | F21: =SUM(F10,F19) -> 1.8390301e+08 | H21: =SUM(H10,H19) -> 8.0670051e+08
B23: LIABILITIES AND OWNER'S EQUITY
B24: CURRENT LIABILITIES
B25: Accounts Payable | D25: =E6 -> 0 | E25: 0 | F25: 0 | H25: =SUM(D25:F25) -> 0
B26: Short-Term Loans | D26: 0 | E26: 0 | F26: 0 | H26: =SUM(D26:F26) -> 0
B27: Income Taxes Payable | D27: 0 | E27: 0 | F27: 0 | H27: =SUM(D27:F27) -> 0
B28: Accrued Salaries and Wages | D28: ='CASH FLOW STATEMENT'!C19 -> 14760000 | E28: ='CASH FLOW STATEMENT'!D19 -> 14760000 | F28: ='CASH FLOW STATEMENT'!E19 -> 14760000 | H28: =SUM(D28:F28) -> 44280000
B29: Unearned Revenue | D29: 0 | E29: 0 | F29: 0 | H29: =SUM(D29:F29) -> 0
B30: Current Portion of Long-Term Debt | D30: 0 | E30: 0 | F30: 0 | H30: =SUM(D30:F30) -> 0
B31: TOTAL CURRENT LIABILITIES | D31: =SUM(D25:D30) -> 14760000 | E31: =SUM(E25:E30) -> 14760000 | F31: =SUM(F25:F30) -> 14760000 | H31: =SUM(H24:H30) -> 44280000
B32: LONG-TERM LIABILITIES | D32: 0 | E32: 0 | F32: 0 | H32: =SUM(D32:F32) -> 0
B33: Long-Term Debt | D33: 0 | E33: 0 | F33: 0 | H33: =SUM(D33:F33) -> 0
B34: Income Tax | D34: =D17 -> 0 | E34: =E17 -> 0 | F34: =F17 -> 27967057 | H34: =SUM(D34:F34) -> 27967057
B35: Other | D35: 0 | E35: 0 | F35: 0 | H35: =SUM(D35:F35) -> 0
B36: TOTAL LONG-TERM LIABILITIES | D36: =SUM(D32:D35) -> 0 | E36: =SUM(E32:E35) -> 0 | F36: =SUM(F32:F35) -> 27967057 | H36: =SUM(H32:H35) -> 27967057
B37: OWNER'S EQUITY | D37: 0 | E37: 0 | F37: 0 | H37: =SUM(D37:F37) -> 0
B38: Owner's Investment | D38: =D6+D7+D14-1089522.29 -> 4.7710454e+08 | E38: =E6+E7 -> 0 | F38: ='INCOME STATEMENT'!F42 -> 0 | H38: =SUM(D38:F38) -> 4.7710454e+08
B39: Retained Earnings | D39: =D12 -> 0 | E39: =E12 -> 1.1122248e+08 | F39: =F12 -> 1.3924548e+08 | H39: =SUM(D39:F39) -> 2.5046796e+08
B40: Others | D40: =SUM('CASH FLOW STATEMENT'!C26:C27) -> 4020000 | E40: =SUM('CASH FLOW STATEMENT'!D26:D27) -> 3600000 | F40: =SUM('CASH FLOW STATEMENT'!E26:E27) -> 3600000 | H40: =SUM(D40:F40) -> 11220000
D41: -1000000.6 | E41: -1669522.9 | F41: =E41 -> -1669522.9 | H41: =SUM(D41:F41) -> -4339046.4
B42: TOTAL OWNER'S EQUITY | D42: =SUM(D37:D41) -> 4.8012454e+08 | E42: =SUM(E37:E41) -> 1.1315296e+08 | F42: =SUM(F37:F41) -> 1.4117595e+08 | H42: =SUM(H37:H41) -> 7.3445346e+08
B44: TOTAL LIABILITIES AND OWNER'S EQUITY | D44: =SUM(D31,D36,D42) -> 4.9488454e+08 | E44: =SUM(E31,E36,E42) -> 1.2791296e+08 | F44: =SUM(F31,F36,F42) -> 1.8390301e+08 | H44: =SUM(H31,H36,H42) -> 8.0670051e+08
D46: =D21-D44 -> 0 | E46: =E21-E44 -> 0 | F46: =F21-F44 -> 0 | H46: =H21-H44 -> 0

Sheet REVENUE GENERATION
B3: Revenue Stream | C3: JANUARY | D3: FEBRUARY | E3: MARCH | F3: APRIL | G3: MAY | H3: JUNE | I3: JULY | J3: AUGUST | K3: SEPTEMBER | L3: OCTOBER | M3: NOVEMBER | N3: DECEMBER | O3: Projected Annual Revenue
B4: Bike Rental | C4: =G13 -> 11160000 | D4: =N13 -> 10080000 | E4: =G22 -> 11160000 | F4: =N22 -> 10800000 | G4: =G30 -> 11160000 | H4: =N30 -> 10800000 | I4: =G39 -> 11160000 | J4: =N39 -> 11160000 | K4: =G48 -> 10800000 | L4: =N48 -> 11160000 | M4: =G57 -> 10800000 | N4: =N57 -> 11160000 | O4: =SUM(C4:N4) -> 131400000
B5: Battery Swap | C5: =G14 -> 0 | D5: =N14 -> 0 | E5: =G23 -> 0 | F5: =N23 -> 0 | G5: =G31 -> 0 | H5: =N31 -> 0 | I5: =G40 -> 0 | J5: =N40 -> 0 | K5: =G49 -> 0 | L5: =N49 -> 0 | M5: =G58 -> 0 | N5: =N58 -> 0 | O5: =SUM(C5:N5) -> 0
O6: 0
O7: 0
O8: =SUM(O4:O6) -> 131400000
C10: =AVERAGE(C4:N4) -> 10950000 | D10: =C10*12 -> 131400000 | F10: =1208*50 -> 60400 | G10: =F10*30 -> 1812000 | H10: =C4-G10 -> 9348000
B11: JANUARY | I11: FEBRUARY
B12: Revenue Stream | C12: Sale/Rental Price | D12: NO. of Bikes | E12: Projected Daily Revenue | F12: Monthly Operating Days | G12: Projected Monthly Revenue | I12: Revenue Stream | J12: Sale/Rental Price | K12: NO. of Bikes | L12: Projected Daily Revenue | M12: Monthly Operating Days | N12: =G12 -> Projected Monthly Revenue
B13: Bike Rental | C13: 6000 | D13: 60 | E13: =C13*D13 -> 360000 | F13: 31 | G13: =F13*E13 -> 11160000 | I13: Bike Rental | J13: 6000 | K13: =D13-D14 -> 60 | L13: =J13*K13 -> 360000 | M13: 28 | N13: =M13*L13 -> 10080000
B14: Bike Sales | C14: 1300000 | D14: 0 | E14: =C14*D14 -> 0 | G14: =F14*E14 -> 0 | I14: Bike Sales | J14: 1300000 | K14: 0 | L14: =J14*K14 -> 0 | N14: =M14*L14 -> 0
G15: 0 | N15: 0
G16: 0 | N16: 0
G17: =SUM(G13:G15) -> 11160000 | N17: =SUM(N13:N15) -> 10080000
B20: MARCH | I20: APRIL
B21: Revenue Stream | C21: Sale/Rental Price | D21: NO. of Bikes | E21: Projected Daily Revenue | F21: Monthly Operating Days | G21: =N21 -> Projected Monthly Revenue | I21: Revenue Stream | J21: Sale/Rental Price | K21: NO. of Bikes | L21: Projected Daily Revenue | M21: Monthly Operating Days | N21: =N12 -> Projected Monthly Revenue
B22: Bike Rental | C22: 6000 | D22: =K13-K14 -> 60 | E22: =C22*D22 -> 360000 | F22: 31 | G22: =F22*E22 -> 11160000 | I22: Bike Rental | J22: 6000 | K22: =D22-D23 -> 60 | L22: =J22*K22 -> 360000 | M22: 30 | N22: =M22*L22 -> 10800000
B23: Bike Sales | C23: 1300000 | D23: 0 | E23: =C23*D23 -> 0 | G23: =F23*E23 -> 0 | I23: Bike Sales | J23: 1300000 | K23: 0 | L23: =J23*K23 -> 0 | N23: =M23*L23 -> 0
G24: 0 | N24: 0
G25: 0 | N25: 0
G26: =SUM(G22:G24) -> 11160000 | N26: =SUM(N22:N24) -> 10800000
B28: MAY | I28: JUNE
B29: Revenue Stream | C29: Sale/Rental Price | D29: NO. of Bikes | E29: Projected Daily Revenue | F29: Monthly Operating Days | G29: =G21 -> Projected Monthly Revenue | I29: Revenue Stream | J29: Sale/Rental Price | K29: NO. of Bikes | L29: Projected Daily Revenue | M29: Monthly Operating Days | N29: =G29 -> Projected Monthly Revenue
B30: Bike Rental | C30: 6000 | D30: =K22-K23 -> 60 | E30: =C30*D30 -> 360000 | F30: 31 | G30: =F30*E30 -> 11160000 | I30: Bike Rental | J30: 6000 | K30: =D30-D31 -> 60 | L30: =J30*K30 -> 360000 | M30: 30 | N30: =M30*L30 -> 10800000
B31: Bike Sales | C31: 1300000 | D31: 0 | E31: =C31*D31 -> 0 | G31: =F31*E31 -> 0 | I31: Bike Sales | J31: 1300000 | K31: 0 | L31: =J31*K31 -> 0 | N31: =M31*L31 -> 0
G32: 0 | N32: 0
G33: 0 | N33: 0
G34: =SUM(G30:G32) -> 11160000 | N34: =SUM(N30:N32) -> 10800000
B37: JULY | I37: AUGUST
B38: Revenue Stream | C38: Sale/Rental Price | D38: NO. of Bikes | E38: Projected Daily Revenue | F38: Monthly Operating Days | G38: =N38 -> Projected Monthly Revenue | I38: Revenue Stream | J38: Sale/Rental Price | K38: NO. of Bikes | L38: Projected Daily Revenue | M38: Monthly Operating Days | N38: =N29 -> Projected Monthly Revenue
B39: Bike Rental | C39: 6000 | D39: =K30-K31 -> 60 | E39: =C39*D39 -> 360000 | F39: 31 | G39: =F39*E39 -> 11160000 | I39: Bike Rental | J39: 6000 | K39: =D39-D40 -> 60 | L39: =J39*K39 -> 360000 | M39: 31 | N39: =M39*L39 -> 11160000
B40: Bike Sales | C40: 1300000 | D40: 0 | E40: =C40*D40 -> 0 | G40: =F40*E40 -> 0 | I40: Bike Sales | J40: 1300000 | K40: 0 | L40: =J40*K40 -> 0 | N40: =M40*L40 -> 0
G41: 0 | N41: 0
G42: 0 | N42: 0
G43: =SUM(G39:G41) -> 11160000 | N43: =SUM(N39:N41) -> 11160000
B46: SEPTEMBER | I46: OCTOBER
B47: Revenue Stream | C47: Sale/Rental Price | D47: NO. of Bikes | E47: Projected Daily Revenue | F47: Monthly Operating Days | G47: =N47 -> Projected Monthly Revenue | I47: Revenue Stream | J47: Sale/Rental Price | K47: NO. of Bikes | L47: Projected Daily Revenue | M47: Monthly Operating Days | N47: =N38 -> Projected Monthly Revenue
B48: Bike Rental | C48: 6000 | D48: =K39-K40 -> 60 | E48: =C48*D48 -> 360000 | F48: 30 | G48: =F48*E48 -> 10800000 | I48: Bike Rental | J48: 6000 | K48: =D48-D49 -> 60 | L48: =J48*K48 -> 360000 | M48: 31 | N48: =M48*L48 -> 11160000
B49: Bike Sales | C49: 1300000 | D49: 0 | E49: =C49*D49 -> 0 | G49: =F49*E49 -> 0 | I49: Bike Sales | J49: 1300000 | K49: 0 | L49: =J49*K49 -> 0 | N49: =M49*L49 -> 0
G50: 0 | N50: 0
...

Sheet FLEET INVENTORY
C2: Fleet Inventory
C4: Tricycles | D4: Year 1 | E4: Year 2 | F4: Year 3 | G4: Year 4 | H4: Year 5 | I4: Total
D5: Units | E5: Units | F5: Units | G5: Units | H5: Units | I5: Units
C6: Opening | E6: =D9 -> 60 | F6: =E9 -> 60 | G6: =F9 -> 60 | H6: =G9 -> 60 | I6: =D6 -> 0
C7: Addition | D7: 60 | E7: ='[1]Facility Repayment Plan'!I12 -> 0 | F7: ='[1]Facility Repayment Plan'!N12 -> 0 | G7: ='[1]Facility Repayment Plan'!S12 -> 0 | H7: ='[1]Facility Repayment Plan'!X12 -> 0 | I7: =SUM(D7:H7) -> 60
C8: Disposal | I8: =SUM(D8:H8) -> 0
C9: Closing | D9: =D6+D7-D8 -> 60 | E9: =E6+E7-E8 -> 60 | F9: =F6+F7-F8 -> 60 | G9: =G6+G7-G8 -> 60 | H9: =H6+H7-H8 -> 60 | I9: =H9 -> 60

Sheet CAPEX
C3: Machinery - Bikes
D4: Year 1 | E4: Year 2 | F4: Year 3 | G4: Year 4 | H4: Year 5 | I4: Total
C5: Cost | D5: NGN | E5: NGN | F5: NGN | G5: NGN | H5: NGN | I5: NGN
C6: Opening | E6: =D9 -> 68647500 | F6: =E9 -> 68647500 | G6: =F9 -> 68647500 | H6: =G9 -> 68647500 | I6: =D6 -> 0
C7: Additions | D7: ='FLEET INVENTORY'!D7*1144125 -> 68647500 | E7: 0 | F7: =E7 -> 0 | G7: =F7 -> 0 | H7: =G7 -> 0 | I7: =SUM(D7:H7) -> 68647500
C8: Disposal | D8: 0 | E8: 0 | F8: 0 | G8: 0 | H8: 0 | I8: =SUM(D8:H8) -> 0
C9: Closing | D9: =D6+D7-D8 -> 68647500 | E9: =E6+E7-E8 -> 68647500 | F9: =F6+F7-F8 -> 68647500 | G9: =G6+G7-G8 -> 68647500 | H9: =H6+H7-H8 -> 68647500 | I9: =H9 -> 68647500
E12: Bike assembly
E13: ='FLEET INVENTORY'!D7 -> 60 | F13: 7000 | G13: =F13*E13 -> 420000
C16: Rent
D17: Year 1 | E17: Year 2 | F17: Year 3 | G17: Year 4 | H17: Year 5 | I17: Total
C18: Cost | D18: NGN | E18: NGN | F18: NGN | G18: NGN | H18: NGN | I18: NGN
C19: Opening | E19: =D22 -> 1000000 | F19: =E22 -> 2000000 | G19: =F22 -> 3000000 | H19: =G22 -> 4000000 | I19: =D19 -> 0
C20: Additions | D20: 1000000 | E20: =D20 -> 1000000 | F20: =E20 -> 1000000 | G20: =F20 -> 1000000 | H20: =G20 -> 1000000 | I20: =SUM(D20:H20) -> 5000000
C21: Disposal | D21: ='[1]Facility Repayment Plan'!D25 -> 0 | E21: ='[1]Facility Repayment Plan'!E25 -> 0 | F21: ='[1]Facility Repayment Plan'!F25 -> 0 | G21: ='[1]Facility Repayment Plan'!G25 -> 0 | H21: ='[1]Facility Repayment Plan'!H25 -> 0 | I21: =SUM(D21:H21) -> 0
C22: Closing | D22: =D19+D20-D21 -> 1000000 | E22: =E19+E20-E21 -> 2000000 | F22: =F19+F20-F21 -> 3000000 | G22: =G19+G20-G21 -> 4000000 | H22: =H19+H20-H21 -> 5000000 | I22: =H22 -> 5000000
C25: Solar Installation
D26: Year 1 | E26: Year 2 | F26: Year 3 | G26: Year 4 | H26: Year 5 | I26: Total
C27: Cost | D27: NGN | E27: NGN | F27: NGN | G27: NGN | H27: NGN | I27: NGN
C28: Opening | E28: =D31 -> 6000000 | F28: =E31 -> 6000000 | G28: =F31 -> 6000000 | H28: =G31 -> 6000000 | I28: =D28 -> 0
C29: Additions | D29: 6000000 | E29: 0 | F29: =E29 -> 0 | G29: =F29 -> 0 | H29: =G29 -> 0 | I29: =SUM(D29:H29) -> 6000000
C30: Disposal | D30: ='[1]Facility Repayment Plan'!D34 -> 0 | E30: ='[1]Facility Repayment Plan'!E34 -> 0 | F30: ='[1]Facility Repayment Plan'!F34 -> 0 | G30: ='[1]Facility Repayment Plan'!G34 -> 0 | H30: ='[1]Facility Repayment Plan'!H34 -> 0 | I30: =SUM(D30:H30) -> 0
C31: Closing | D31: =D28+D29-D30 -> 6000000 | E31: =E28+E29-E30 -> 6000000 | F31: =F28+F29-F30 -> 6000000 | G31: =G28+G29-G30 -> 6000000 | H31: =H28+H29-H30 -> 6000000 | I31: =H31 -> 6000000
C34: Equipments
C35: 48V-30ah Lithium ION Battery(Lipo4) | D35: 184 | E35: 592911 | F35: =D35*E35 -> 109095624
C36: Battery Swap Cabinet(12 lockers) 220 -240VAC input, 48 -60VDC output | D36: 8 | E36: 5793510 | F36: =D36*E36 -> 46348080
C37: 450W Solar Panels Mono Crystalline | D37: 8 | E37: 242554.5 | F37: =D37*E37 -> 1940436
C38: lithium-ion AC-DC battery Charger 10ah-AK-CAN-GLI | D38: 10 | E38: 80936.25 | F38: =D38*E38 -> 809362.5
C39: 503450 3.7V Intelligent ECU | D39: 60 | E39: 83733 | F39: =D39*E39 -> 5023980
C40: ECU Battery | D40: 60 | E40: 1695 | F40: =D40*E40 -> 101700
C41: ZD-133 Industrial Socket | D41: 8 | E41: 19763.7 | F41: =D41*E41 -> 158109.6
C42: ZD-033 PLugs | D42: 8 | E42: 12051.45 | F42: =D42*E42 -> 96411.6
C43: 2P63A-Isolator Switch | D43: 8 | E43: 10661.55 | F43: =D43*E43 -> 85292.4
C44: KBTM0309-Bicycle Truing Machine | D44: 1 | E44: 245775 | F44: =D44*E44 -> 245775
C45: PV Solar Panels Mono-Crystalline | D45: 10 | E45: 210000 | F45: =D45*E45 -> 2100000
C46: Solar charge Controllers - PWM | D46: 5 | E46: 75000 | F46: =D46*E46 -> 375000
... C52: Panel Rack | D52: 5 | E52: 20000 | F52: =D52*E52 -> 100000
E53: 0
C55: Total Equipments | F55: =SUM(F35:F54) -> 1.6690477e+08
C59: EQUIPMENTS
...

Sheet OPEX
B2: Operation Cost
B3: Direct Cost | D3: Units | E3: Batch | F3: Total Personnel | G3: Monthly Pay Per Personnel | H3: Monthly Total Pay | I3: Annual Total Pay
G4: NGN | H4: NGN | I4: NGN
B8: Drivers- Bike
B9: Peak | D9: 0 | E9: 0 | F9: =D9*E9 -> 0 | G9: 0 | H9: =G9*F9 -> 0 | I9: =H9*12 -> 0
B10: Sub-Total | I10: =SUM(I9:I9) -> 0
B12: Engineer | D12: 1 | E12: 1 | F12: =D12*E12 -> 1 | G12: 120000 | H12: =G12*F12 -> 120000 | I12: =H12*12 -> 1440000
B13: Supervisor | D13: 1 | E13: 1 | F13: =D13*E13 -> 1 | G13: 100000 | H13: =G13*F13 -> 100000 | I13: =H13*12 -> 1200000
B14: Cashier | D14: 1 | E14: 1 | F14: =D14*E14 -> 1 | G14: 120000 | H14: =G14*F14 -> 120000 | I14: =H14*12 -> 1440000 | K14: `
B15: Attendant | D15: 8 | E15: 1 | F15: =D15*E15 -> 8 | G15: 35000 | H15: =G15*F15 -> 280000 | I15: =H15*12 -> 3360000
B16: Manager | D16: 1 | E16: 1 | F16: =D16*E16 -> 1 | G16: 180000 | H16: =G16*F16 -> 180000 | I16: =H16*12 -> 2160000
H17: =G17*F17 -> 0 | I17: =H17*12 -> 0 | J17: =AVERAGE(G12:G16) -> 111000 | K17: =AVERAGE(H12:H16) -> 160000
B18: Security Personnel | D18: 1 | E18: 1 | F18: 2 | G18: =G15 -> 35000 | H18: =G18*F18 -> 70000 | I18: =H18*12 -> 840000
B19: Cleaning Personeel | D19: 1 | E19: 1 | F19: 2 | G19: =G16 -> 180000 | H19: =G19*F19 -> 360000 | I19: =H19*12 -> 4320000
H20: =G20*F20 -> 0 | I20: =H20*12 -> 0
H21: =G21*F21 -> 0 | I21: =H21*12 -> 0
B22: Total Direct Cost | H22: =SUM(H12:H21) -> 1230000 | I22: =SUM(I12:I21) -> 14760000
B26: Overheads
D27: Units | E27: Cluster | F27: Total Units | G27: Monthly Pay Per Personnel | H27: Monthly Total Pay | I27: Annual Total Pay | J27: Remarks
B28: Salaries and Wages | G28: NGN | H28: NGN | I28: NGN
B29: Bike Assembly | D29: 60 | E29: 1 | F29: 60 | G29: 7000 | H29: =G29*F29 -> 420000 | I29: =H29*12 -> 5040000 | J29: Each cluster contains 25 utility
B36: Total | H36: =SUM(H29:H35) -> 420000 | I36: =SUM(I29:I35) -> 5040000
D37: =SUM(OPEX!H9:H35) -> 2880000
B38: Repairs and Maintenance | D38: Units | G38: Maintenance Price Per Bike | H38: =I38 -> Annual Total Charge | I38: Annual Total Charge
G39: NGN | H39: NGN | I39: NGN
B40: Tricycle | D40: 60 | G40: 60000 | H40: =G40*D40 -> 3600000 | I40: =H40 -> 3600000
B41: Total | I41: =SUM(I40:I40) -> 3600000
B43: Energy and Power | D43: Units | E43: Frequency per Month | G43: Monthly charge Per Unit | H43: Monthly Total charge | I43: Annual Total Charge
G44: NGN | H44: NGN | I44: NGN
B45: Tricycle | D45: 0 | E45: ='[1]Parameters and Summary'!E22*'[1]Parameters and Summary'!E21 -> 24 | G45: 6500 | H45: =G45*E45*D45 -> 0 | I45: =H45*12 -> 0
B46: Total | I46: =SUM(I45:I45) -> 0
