Workbook

Sheet Summary Of Financials
C5: SUMMARY OF FINANCIALS
C6: DESCRIPTION | D6: YEAR 1 | E6: YEAR 2 | F6: YEAR 3 | G6: YEAR 4 | H6: YEAR 5 | I6: YEAR 6 | J6: YEAR 7 | K6: YEAR 8 | L6: YEAR 9 | M6: YEAR 10 | N6: TOTAL
C7: Projected Revenue Generation | D7: ='Income Statement'!K14 -> 30653209512 | E7: ='Income Statement'!N14 -> 6.437174e+10 | F7: ='Income Statement'!Q14 -> 1.2378754e+11 | G7: ='Income Statement'!T14 -> 1.7330256e+11 | H7: ='Income Statement'!W14 -> 2.2745961e+11 | I7: ='Income Statement'!Z14 -> 3.3883259e+11 | J7: ='Income Statement'!AC14 -> 2.5077422e+11 | K7: ='Income Statement'!AF14 -> 2.6331293e+11 | L7: ='Income Statement'!AI14 -> 2.7647857e+11 | M7: ='Income Statement'!AL14 -> 3.903025e+11 | N7: =SUM(D7:M7) -> 2.1392755e+12
C8: Less: Direct Cost | D8: ='Income Statement'!K29 -> 2.7379561e+10 | E8: ='Income Statement'!N29 -> 4.1652759e+10 | F8: ='Income Statement'!Q29 -> 6.3578396e+10 | G8: ='Income Statement'!T29 -> 8.7696597e+10 | H8: ='Income Statement'!W29 -> 1.1422662e+11 | I8: ='Income Statement'!Z29 -> 1.148064e+11 | J8: ='Income Statement'!AC29 -> 1.1544416e+11 | K8: ='Income Statement'!AF29 -> 1.161457e+11 | L8: ='Income Statement'!AI29 -> 1.1691739e+11 | M8: ='Income Statement'!AL29 -> 1.1776625e+11 | N8: =SUM(D8:M8) -> 9.1561385e+11
C9: Gross Profit | D9: ='Income Statement'!K31 -> 3.2736482e+09 | E9: ='Income Statement'!N31 -> 2.2718981e+10 | F9: ='Income Statement'!Q31 -> 6.0209145e+10 | G9: ='Income Statement'!T31 -> 8.5605961e+10 | H9: ='Income Statement'!W31 -> 1.1323299e+11 | I9: ='Income Statement'!Z31 -> 2.2402619e+11 | J9: ='Income Statement'!AC31 -> 1.3533005e+11 | K9: ='Income Statement'!AF31 -> 1.4716723e+11 | L9: ='Income Statement'!AI31 -> 1.5956118e+11 | M9: ='Income Statement'!AL31 -> 2.7253625e+11 | N9: =SUM(D9:M9) -> 1.2236616e+12
C10: Operating and Maintenance Cost | D10: ='Income Statement'!K63 -> 5.2767062e+09 | E10: ='Income Statement'!N63 -> 8.1710879e+09 | F10: ='Income Statement'!Q63 -> 1.5090476e+10 | G10: ='Income Statement'!T63 -> 2.4188114e+10 | H10: ='Income Statement'!W63 -> 3.5248346e+10 | I10: ='Income Statement'!Z63 -> 5.1893013e+10 | J10: ='Income Statement'!AC63 -> 4.6102183e+10 | K10: ='Income Statement'!AF63 -> 3.7756276e+10 | L10: ='Income Statement'!AI63 -> 3.0804392e+10 | M10: ='Income Statement'!AL63 -> 2.886227e+10 | N10: =SUM(D10:M10) -> 2.8339286e+11
C11: Net Earnings before Tax | D11: ='Income Statement'!K64 -> -2.003058e+09 | E11: ='Income Statement'!N64 -> 1.4547893e+10 | F11: ='Income Statement'!Q64 -> 4.5118669e+10 | G11: ='Income Statement'!T64 -> 6.1417847e+10 | H11: ='Income Statement'!W64 -> 7.7984643e+10 | I11: ='Income Statement'!Z64 -> 1.7213317e+11 | J11: ='Income Statement'!AC64 -> 8.922787e+10 | K11: ='Income Statement'!AF64 -> 1.0941095e+11 | L11: ='Income Statement'!AI64 -> 1.2875679e+11 | M11: ='Income Statement'!AL64 -> 2.4367398e+11 | N11: =SUM(D11:M11) -> 9.4026875e+11
C12: Less: Tax | D12: ='Income Statement'!K70 -> 0 | E12: ='Income Statement'!N70 -> 4.8008048e+09 | F12: ='Income Statement'!Q70 -> 1.4889161e+10 | G12: ='Income Statement'!T70 -> 2.0267889e+10 | H12: ='Income Statement'!W70 -> 2.5734932e+10 | I12: ='Income Statement'!Z70 -> 5.6803947e+10 | J12: ='Income Statement'!AC70 -> 2.9445197e+10 | K12: ='Income Statement'!AF70 -> 3.6105613e+10 | L12: ='Income Statement'!AI70 -> 4.248974e+10 | M12: ='Income Statement'!AL70 -> 8.0412413e+10 | N12: =SUM(D12:M12) -> 3.109497e+11
C13: Less: Repayment Expense - Long term facility | I13: ='[1]Income Statement'!Z67 -> 1.8717388e+11 | J13: ='[1]Income Statement'!AC67 -> 1.9278909e+11 | K13: ='[1]Income Statement'!AF67 -> 1.9857277e+11 | L13: ='[1]Income Statement'!AI67 -> 2.0452995e+11 | M13: ='[1]Income Statement'!AL67 -> 2.1066585e+11 | N13: =SUM(D13:M13) -> 9.9373153e+11
C14: Net Earnings after Tax | D14: ='Income Statement'!K71 -> -2.003058e+09 | E14: ='Income Statement'!N71 -> 9.7470885e+09 | F14: ='Income Statement'!Q71 -> 3.0229508e+10 | G14: ='Income Statement'!T71 -> 4.1149957e+10 | H14: ='Income Statement'!W71 -> 5.2249711e+10 | I14: ='Income Statement'!Z71 -> 1.1532923e+11 | J14: ='Income Statement'!AC71 -> 5.9782673e+10 | K14: ='Income Statement'!AF71 -> 7.3305336e+10 | L14: ='Income Statement'!AI71 -> 8.6267048e+10 | M14: ='Income Statement'!AL67 -> 2.4367398e+11 | N14: =SUM(D14:M14) -> 7.0973147e+11
C15: Discounted Factor | D15: 0.909 | E15: 0.826 | F15: 0.751 | G15: 0.683 | H15: 0.621 | I15: 0.564 | J15: 0.513 | K15: 0.467 | L15: 0.424 | M15: 0.386
C16: Present Value | D16: =D15*D14 -> -1.8207797e+09 | E16: =E15*E14 -> 8.0510951e+09 | F16: =F15*F14 -> 2.2702361e+10 | G16: =G15*G14 -> 2.8105421e+10 | H16: =H15*H14 -> 3.244707e+10 | I16: =I15*I14 -> 6.5045683e+10 | J16: =J15*J14 -> 3.0668511e+10 | K16: =K15*K14 -> 3.4233592e+10 | ... M16: =M15*M14 -> 9.4058155e+10 | N16: =SUM(D16:M16) -> 3.5006834e+11
C18: Projected Total Income | D18: =D7 -> 30653209512 | E18: =E7 -> 6.437174e+10 | F18: =F7 -> 1.2378754e+11 | G18: =G7 -> 1.7330256e+11 | H18: =H7 -> 2.2745961e+11 | I18: =I7 -> 3.3883259e+11 | J18: =J7 -> 2.5077422e+11 | K18: =K7 -> 2.6331293e+11 | ... M18: =M7 -> 3.903025e+11 | N18: =SUM(D18:M18) -> 2.1392755e+12
C19: Total Investment | D19: ='Facility Repayment Plan'!C29 -> 1.6145783e+11 | E19: ='Facility Repayment Plan'!D29 -> 1.7760361e+11 | F19: ='Facility Repayment Plan'!E29 -> 1.9536397e+11 | G19: ='Facility Repayment Plan'!F29 -> 2.1490037e+11 | H19: ='Facility Repayment Plan'!G29 -> 2.3639041e+11 | N19: =SUM(D19:M19) -> 9.857162e+11
C20: Repayment Plan | D20: ='[1]Facility Repayment Plan'!C30 -> 0 | E20: ='[1]Facility Repayment Plan'!D30 -> 0 | F20: ='[1]Facility Repayment Plan'!E30 -> 0 | G20: ='[1]Facility Repayment Plan'!F30 -> 0 | H20: ='[1]Facility Repayment Plan'!G30 -> 0 | I20: =I13 -> 1.8717388e+11 | J20: =J13 -> 1.9278909e+11 | K20: =K13 -> 1.9857277e+11 | L20: =L13 -> 2.0452995e+11 | M20: =M13 -> 2.1066585e+11 | N20: =SUM(D20:M20) -> 9.9373153e+11

Sheet Summary Of Financials $
C5: SUMMARY OF FINANCIALS $
C6: DESCRIPTION | D6: YEAR 1 | E6: YEAR 2 | F6: YEAR 3 | G6: YEAR 4 | H6: YEAR 5 | I6: YEAR 6 | J6: YEAR 7 | K6: YEAR 8 | L6: YEAR 9 | M6: YEAR 10 | N6: TOTAL
C7: Projected Revenue Generation | D7: =('Income Statement'!K14)/952.639 -> 32177152 | E7: =('Income Statement'!N14)/1047.9029 -> 61429108 | F7: =('Income Statement'!Q14)/1152.69319 -> 1.0738984e+08 | G7: =('Income Statement'!T14)/1267.962509 -> 1.3667798e+08 | H7: =('Income Statement'!W14)/1394.7587599 -> 1.6308168e+08 | I7: =('Income Statement'!Z14)/1534.23463589 -> 2.2084796e+08 | J7: =('Income Statement'!AC14)/1687.658099479 -> 1.4859302e+08 | K7: =('Income Statement'!AF14)/1856.4239094269 -> 1.4183879e+08 | L7: =('Income Statement'!AI14)/2042.06630036959 -> 1.3539158e+08 | M7: =('Income Statement'!AL14)/2246.27293040655 -> 1.737556e+08 | N7: =SUM(D7:M7) -> 1.3211827e+09
C8: Less: Direct Cost | D8: =('Income Statement'!K29)/952.639 -> 28740752 | E8: =('Income Statement'!N29)/1047.9029 -> 39748682 | F8: =('Income Statement'!Q29)/1152.69319 -> 55156391 | G8: =('Income Statement'!T29)/1267.962509 -> 69163399 | H8: =('Income Statement'!W29)/1394.7587599 -> 81897043 | I8: =('Income Statement'!Z29)/1534.23463589 -> 74829755 | J8: =('Income Statement'!AC29)/1687.658099479 -> 68404947 | K8: =('Income Statement'!AF29)/1856.4239094269 -> 62564213 | L8: =('Income Statement'!AI29)/2042.06630036959 -> 57254455 | M8: =('Income Statement'!AL29)/2246.27293040655 -> 52427402 | N8: =SUM(D8:M8) -> 5.9018704e+08
C9: Gross Profit | D9: =('Income Statement'!K31)/952.639 -> 3436399.5 | E9: =('Income Statement'!N31)/1047.9029 -> 21680426 | F9: =('Income Statement'!Q31)/1152.69319 -> 52233453 | G9: =('Income Statement'!T31)/1267.962509 -> 67514584 | H9: =('Income Statement'!W31)/1394.7587599 -> 81184641 | I9: =('Income Statement'!Z31)/1534.23463589 -> 1.460182e+08 | J9: =('Income Statement'!AC31)/1687.658099479 -> 80188074 | K9: =('Income Statement'!AF31)/1856.4239094269 -> 79274580 | L9: =('Income Statement'!AI31)/2042.06630036959 -> 78137120 | M9: =('Income Statement'!AL31)/2246.27293040655 -> 1.213282e+08 | N9: =SUM(D9:M9) -> 7.3099568e+08
C10: Operating and Maintenance Cost | D10: =('Income Statement'!K63)/952.639 -> 5539040.7 | E10: =('Income Statement'!N63)/1047.9029 -> 7797562 | F10: =('Income Statement'!Q63)/1152.69319 -> 13091494 | G10: =('Income Statement'!T63)/1267.962509 -> 19076364 | H10: =('Income Statement'!W63)/1394.7587599 -> 25272002 | I10: =('Income Statement'!Z63)/1534.23463589 -> 33823387 | J10: =('Income Statement'!AC63)/1687.658099479 -> 27317253 | K10: =('Income Statement'!AF63)/1856.4239094269 -> 20338176 | L10: =('Income Statement'!AI63)/2042.06630036959 -> 15084913 | M10: =('Income Statement'!AL63)/2246.27293040655 -> 12848960 | N10: =SUM(D10:M10) -> 1.8018915e+08
C11: Net Earnings before Tax | D11: =('Income Statement'!K64)/952.639 -> -2102641.2 | E11: =('Income Statement'!N64)/1047.9029 -> 13882864 | F11: =('Income Statement'!Q64)/1152.69319 -> 39141959 | G11: =('Income Statement'!T64)/1267.962509 -> 48438220 | H11: =('Income Statement'!W64)/1394.7587599 -> 55912639 | I11: =('Income Statement'!Z64)/1534.23463589 -> 1.1219482e+08 | J11: =('Income Statement'!AC64)/1687.658099479 -> 52870821 | K11: =('Income Statement'!AF64)/1856.4239094269 -> 58936404 | L11: =('Income Statement'!AI64)/2042.06630036959 -> 63052208 | M11: =('Income Statement'!AL64)/2246.27293040655 -> 1.0847924e+08 | N11: =SUM(D11:M11) -> 5.5080653e+08
C12: Less: Tax | D12: =('Income Statement'!K70)/952.639 -> 0 | E12: =('Income Statement'!N70)/1047.9029 -> 4581345.1 | F12: =('Income Statement'!Q70)/1152.69319 -> 12916846 | G12: =('Income Statement'!T70)/1267.962509 -> 15984613 | H12: =('Income Statement'!W70)/1394.7587599 -> 18451171 | I12: =('Income Statement'!Z70)/1534.23463589 -> 37024289 | J12: =('Income Statement'!AC70)/1687.658099479 -> 17447371 | K12: =('Income Statement'!AF70)/1856.4239094269 -> 19449013 | L12: =('Income Statement'!AI70)/2042.06630036959 -> 20807229 | M12: =('Income Statement'!AL70)/2246.27293040655 -> 35798149 | N12: =SUM(D12:M12) -> 1.8246003e+08
C13: Less: Repayment Expense - Long term facility | D13: 0 | E13: 0 | F13: 0 | G13: 0 | H13: 0 | I13: =D19 -> 169484800 | J13: =E19 -> 169484800 | K13: =F19 -> 169484800 | L13: =G19 -> 169484800 | M13: =H19 -> 169484800 | N13: =SUM(D13:M13) -> 847424000
C14: Net Earnings after Tax | D14: =('Income Statement'!K71)/952.639 -> -2102641.2 | E14: =('Income Statement'!N71)/1047.9029 -> 9301518.8 | F14: =('Income Statement'!Q71)/1152.69319 -> 26225112 | G14: =('Income Statement'!T71)/1267.962509 -> 32453607 | H14: =('Income Statement'!W71)/1394.7587599 -> 37461468 | I14: =('Income Statement'!Z71)/1534.23463589 -> 75170527 | J14: =('Income Statement'!AC71)/1687.658099479 -> 35423450 | K14: =('Income Statement'!AF71)/1856.4239094269 -> 39487391 | L14: =('Income Statement'!AI71)/2042.06630036959 -> 42244979 | M14: =('Income Statement'!AL67)/2246.27293040655 -> 1.0847924e+08 | N14: =SUM(D14:M14) -> 4.0414465e+08
C15: Discounted Factor | D15: 0.909 | E15: 0.826 | F15: 0.751 | G15: 0.683 | H15: 0.621 | I15: 0.564 | J15: 0.513 | K15: 0.467 | L15: 0.424 | M15: 0.386
C16: Present Value | D16: =(D15*D14)/952.639 -> -2006.3223 | E16: =(E15*E14)/1047.9029 -> 7331.8382 | F16: =(F15*F14)/1152.69319 -> 17086.125 | G16: =(G15*G14)/1267.962509 -> 17481.443 | H16: =(H15*H14)/1394.7587599 -> 16679.28 | I16: =(I15*I14)/1534.23463589 -> 27633.438 | J16: =(J15*J14)/1687.658099479 -> 10767.72 | K16: =(K15*K14)/1856.4239094269 -> 9933.4055 | L16: =(L15*L14)/2042.06630036959 -> 8771.4445 | M16: =(M15*M14)/2246.27293040655 -> 18641.095 | N16: =SUM(D16:M16) -> 132319.47
D17: 0 | E17: 0 | F17: 0 | G17: 0 | H17: 0 | I17: 0 | J17: 0 | K17: 0 | L17: 0 | M17: 0
C18: Projected Total Income | D18: =(D7)/952.639 -> 33776.857 | E18: =(E7)/1047.9029 -> 58620.992 | F18: =(F7)/1152.69319 -> 93164.291 | G18: =(G7)/1267.962509 -> 107793.39 | H18: =(H7)/1394.7587599 -> 116924.65 | I18: =(I7)/1534.23463589 -> 143946.66 | J18: =(J7)/1687.658099479 -> 88046.875 | K18: =(K7)/1856.4239094269 -> 76404.313 | L18: =(L7)/2042.06630036959 -> 66301.263 | M18: =(M7)/2246.27293040655 -> 77352.845 | N18: =SUM(D18:M18) -> 862332.15
C19: Total Investment | D19: =('Facility Repayment Plan'!C29)/952.639 -> 169484800 | E19: =('Facility Repayment Plan'!D29)/1047.9029 -> 169484800 | F19: =('Facility Repayment Plan'!E29)/1152.69319 -> 169484800 | G19: =('Facility Repayment Plan'!F29)/1267.962509 -> 169484800 | H19: =('Facility Repayment Plan'!G29)/1394.7587599 -> 169484800 | I19: 0 | J19: 0 | K19: 0 | L19: 0 | M19: 0 | N19: =SUM(D19:M19) -> 847424000
C20: Repayment Plan | D20: ='[1]Facility Repayment Plan'!C30 -> 0 | E20: ='[1]Facility Repayment Plan'!D30 -> 0 | F20: ='[1]Facility Repayment Plan'!E30 -> 0 | G20: ='[1]Facility Repayment Plan'!F30 -> 0 | H20: ='[1]Facility Repayment Plan'!G30 -> 0 | I20: =I13 -> 169484800 | J20: =J13 -> 169484800 | K20: =K13 -> 169484800 | L20: =L13 -> 169484800 | M20: =M13 -> 169484800 | N20: =SUM(D20:M20) -> 847424000

Sheet Parameters and Summary
F2: Year 1 | G2: Year 2 | H2: Year 3 | I2: Year 4 | J2: Year 5 | K2: Year 6 | L2: Year 7 | M2: Year 8 | N2: Year 9 | O2: Year 10
C3: Assumptions
C4: Transport Utility Operating Hours per day (hrs) | E4: 24
C5: Human Operating Hours per day/shift (hrs) | E5: 8
C6: Number of Shift per day | E6: 3
C8: Number of trips
C9: Taxi
C10: Peak | D10: 6am- 6pm | E10: 15
C11: Off peak | D11: 6pm- 9pm | E11: 3
C12: Overnight | D12: 9pm - 6am | E12: 1
C15: Bus
C16: Peak | D16: 6am- 6pm | E16: 7
C17: Off peak | D17: 6pm- 9pm | E17: 3
C18: Overnight | D18: 9pm - 6am | E18: 0
C21: Number of operating days per week | E21: 6
C22: Number of operating week per month | E22: 4
C23: Number of operating month per year | E23: 12
C24: Taxi Fare per trip (NGN) | E24: 1500 | F24: 1500 | G24: =F24*1.05 -> 1575 | H24: =G24*1.05 -> 1653.75 | I24: =H24*1.05 -> 1736.4375 | J24: =I24*1.05 -> 1823.2594 | K24: =J24*1.05 -> 1914.4223 | L24: =K24*1.05 -> 2010.1435 | M24: =L24*1.05 -> 2110.6506 | N24: =M24*1.05 -> 2216.1832 | O24: =N24*1.05 -> 2326.9923
C30: Number of PAX Per Trip- Taxi
C31: Peak | D31: 6am- 6pm | E31: 1
C32: Off peak | D32: 6pm- 9pm | E32: 1
C33: Overnight | D33: 9pm - 6am | E33: 1
C35: Number of PAX Per Trip- Bus
C36: Peak | D36: 6am- 6pm | E36: 37
C37: Off peak | D37: 6pm- 11pm | E37: 25
C38: Overnight | D38: 11pm - 6am | E38: 0
C41: Deployment Efficiency
C42: Taxi and Bus
C43: Location | D43: Peak | E43: Off-Peak | F43: Night
C44: Retail and Recreation (+56%) | D44: 1 | E44: 0.75 | F44: 0.1
C45: Supermarket and Pharmacy (+75%) | D45: =D44 -> 1 | E45: =E44 -> 0.75 | F45: =F44 -> 0.1
C46: Parks (+43%) | D46: =D45 -> 1 | E46: =E45 -> 0.75 | F46: =F45 -> 0.1
C47: Workplaces (+73%) | D47: =D46 -> 1 | E47: =E46 -> 0.75 | F47: =F46 -> 0.1
C48: Residential Areas (+19%) | D48: =D47 -> 1 | E48: =E47 -> 0.75 | F48: =F47 -> 0.1
C49: Public Transport (+33%) | D49: =D48 -> 1 | E49: =E48 -> 0.75 | F49: =F48 -> 0.1
C51: Bus
C52: Location | D52: Peak | E52: Off-Peak | F52: Night
C53: Retail and Recreation (+56%) | D53: 1 | E53: 0.75 | F53: 0
C54: Supermarket and Pharmacy (+75%) | D54: =D53 -> 1 | E54: =E53 -> 0.75 | F54: =F53 -> 0
C55: Parks (+43%) | D55: =D54 -> 1 | E55: =E54 -> 0.75 | F55: =F54 -> 0
...

Sheet Exchange Rate growth 
D3: Year 1 | E3: Year 2 | F3: Year 3 | G3: Year 4 | H3: Year 5 | I3: Year 6 | J3: Year 7 | K3: Year 8 | L3: Year 9 | M3: Year 10
D4: NGN | E4: NGN | F4: NGN | G4: NGN | H4: NGN | I4: NGN | J4: NGN | K4: NGN | L4: NGN | M4: NGN
C5: Depreciation Factor | E5: 1.1 | F5: 1.1 | G5: 1.1 | H5: 1.1 | I5: 1.1 | J5: 1.1 | K5: 1.1 | L5: 1.1 | M5: 1.1
C6: Exchange | D6: ='Parameters and Summary'!E70 -> 952.639 | E6: =D6*E5 -> 1047.9029 | F6: =E6*F5 -> 1152.6932 | G6: =F6*G5 -> 1267.9625 | H6: =G6*H5 -> 1394.7588 | I6: =H6*I5 -> 1534.2346 | J6: =I6*J5 -> 1687.6581 | K6: =J6*K5 -> 1856.4239 | L6: =K6*L5 -> 2042.0663 | M6: =L6*M5 -> 2246.2729
D10: 952.639 | E10: 1047.9029 | F10: 1152.6932 | G10: 1267.9625 | H10: 1394.7588 | I10: 1534.2346 | J10: 1687.6581 | K10: 1856.4239 | L10: 2042.0663 | M10: 2246.2729
C14: Inflation | D14: 0.05 | E14: 0.05 | F14: 0.05 | G14: 0.05 | H14: 0.05 | I14: 0.05 | J14: 0.05 | K14: 0.05 | L14: 0.05 | M14: 0.05

Sheet Income Statement
C2: Projected Income Statement
C3: Enhancing Public Transportation in the FCT
E4: Cummulative | H4: 2023 | K4: 45657 | N4: 46022 | Q4: 46387 | T4: 46752 | W4: 47118 | Z4: 47483 | AC4: 47848 | AF4: 48213 | AI4: 48579 | AL4: 48944
H5: Construction/ Deployment Period | K5: 1 | N5: =K5+1 -> 2 | Q5: =N5+1 -> 3 | T5: =Q5+1 -> 4 | W5: =T5+1 -> 5 | Z5: =W5+1 -> 6 | AC5: =Z5+1 -> 7 | AF5: =AC5+1 -> 8 | AI5: =AF5+1 -> 9 | AL5: =AI5+1 -> 10
E6: NGN | F6: RATE | G6: USD | H6: NGN | I6: RATE | J6: USD | K6: NGN | L6: RATE | M6: USD | N6: NGN | O6: RATE | P6: USD | Q6: NGN | R6: RATE | S6: USD | T6: NGN | U6: RATE | V6: USD | W6: NGN | X6: RATE | Y6: USD | Z6: NGN | AA6: RATE | AB6: USD | AC6: NGN | AD6: RATE | AE6: USD | AF6: NGN | AG6: RATE | AH6: USD | AI6: NGN | AJ6: RATE | AK6: USD | AL6: NGN | AM6: RATE | AN6: USD
C7: REVENUE
C9: Transportation Fare
C10: Taxi | E10: =K10+N10+Q10+T10+W10+Z10+AC10+AF10+AI10+AL10 -> 7.8514975e+11 | F10: ='Parameters and Summary'!E70 -> 952.639 | G10: =E10/F10 -> 8.2418392e+08 | I10: =F10 -> 952.639 | J10: =H10/I10 -> 0 | K10: ='Revenue Schedule'!AE31 -> 14990400000 | L10: =I10 -> 952.639 | M10: =K10/L10 -> 15735656 | N10: ='Cashflow Statement'!Q16 -> 31479840000 | O10: ='Exchange Rate growth '!E6 -> 1047.9029 | P10: =N10/O10 -> 30040799 | Q10: ='Cashflow Statement'!T16 -> 49580748000 | R10: ='Exchange Rate growth '!F6 -> 1152.6932 | S10: =Q10/R10 -> 43012962 | T10: ='Cashflow Statement'!W16 -> 69413047200 | U10: ='Exchange Rate growth '!G6 -> 1267.9625 | V10: =T10/U10 -> 54743769 | W10: ='Cashflow Statement'!Z16 -> 91104624450 | X10: ='Exchange Rate growth '!H6 -> 1394.7588 | Y10: =W10/X10 -> 65319270 | Z10: ='Cashflow Statement'!AC16 -> 9.5659856e+10 | AA10: ='Exchange Rate growth '!I6 -> 1534.2346 | AB10: =Z10/AA10 -> 62350213 | AC10: ='Cashflow Statement'!AF16 -> 1.0044285e+11 | AD10: ='Exchange Rate growth '!J6 -> 1687.6581 | AE10: =AC10/AD10 -> 59516112 | AF10: ='Cashflow Statement'!AI16 -> 1.0546499e+11 | AG10: ='Exchange Rate growth '!K6 -> 1856.4239 | AH10: =AF10/AG10 -> 56810834 | AI10: ='Cashflow Statement'!AL16 -> 1.1073824e+11 | AJ10: ='Exchange Rate growth '!L6 -> 2042.0663 | AK10: =AI10/AJ10 -> 54228524 | AL10: ='Cashflow Statement'!AO16 -> 1.1627515e+11 | AM10: ='Exchange Rate growth '!M6 -> 2246.2729 | AN10: =AL10/AM10 -> 51763591
C11: Bus | E11: =K11+N11+Q11+T11+W11+Z11+AC11+AF11+AI11+AL11 -> 1.1541257e+12 | F11: =F10 -> 952.639 | G11: =E11/F11 -> 1.2115037e+09 | I11: =I10 -> 952.639 | K11: ='Revenue Schedule'!AE64 -> 15662809512 | L11: =L10 -> 952.639 | M11: =K11/L11 -> 16441495 | N11: ='Cashflow Statement'!Q17 -> 3.28919e+10 | O11: =O10 -> 1047.9029 | P11: =N11/O11 -> 31388309 | Q11: ='Cashflow Statement'!T17 -> 7.4206793e+10 | R11: =R10 -> 1152.6932 | S11: =Q11/R11 -> 64376882 | T11: ='Cashflow Statement'!W17 -> 1.0388951e+11 | U11: =U10 -> 1267.9625 | V11: =T11/U11 -> 81934213 | W11: ='Cashflow Statement'!Z17 -> 1.3635498e+11 | X11: =X10 -> 1394.7588 | Y11: =W11/X11 -> 97762413 | Z11: ='Cashflow Statement'!AC17 -> 1.4317273e+11 | AA11: =AA10 -> 1534.2346 | AB11: =Z11/AA11 -> 93318667 | AC11: ='Cashflow Statement'!AF17 -> 1.5033137e+11 | AD11: =AD10 -> 1687.6581 | AE11: =AC11/AD11 -> 89076910 | AF11: ='Cashflow Statement'!AI17 -> 1.5784794e+11 | AG11: =AG10 -> 1856.4239 | AH11: =AF11/AG11 -> 85027959 | AI11: ='Cashflow Statement'!AL17 -> 1.6574033e+11 | AJ11: =AJ10 -> 2042.0663 | AK11: =AI11/AJ11 -> 81163052 | AL11: ='Cashflow Statement'!AO17 -> 1.7402735e+11 | AM11: =AM10 -> 2246.2729 | AN11: =AL11/AM11 -> 77473822
C12: ='Cashflow Statement'!C20 -> Fleets Disposal | E12: =K12+N12+Q12+T12+W12+Z12+AC12+AF12+AI12+AL12 -> 100000000000 | F12: =F11 -> 952.639 | G12: =E12/F12 -> 1.0497156e+08 | I12: =I11 -> 952.639 | N12: ='Cashflow Statement'!Q20 -> 0 | Q12: ='Cashflow Statement'!T20 -> 0 | T12: ='Cashflow Statement'!W20 -> 0 | W12: ='Cashflow Statement'!Z20 -> 0 | Z12: ='Cashflow Statement'!AC20 -> 0 | AC12: ='Cashflow Statement'!AF20 -> 0 | AF12: ='Cashflow Statement'!AI20 -> 0 | AI12: ='Cashflow Statement'!AL20 -> 0 | AL12: ='Cashflow Statement'!AO20 -> 100000000000 | AM12: =AM11 -> 2246.2729 | AN12: =AL12/AM12 -> 44518188
C13: Bonds | E13: =K13+N13+Q13+T13+W13+Z13+AC13+AF13+AI13+AL13 -> 100000000000 | F13: =F12 -> 952.639 | G13: =E13/F13 -> 1.0497156e+08 | I13: =I12 -> 952.639 | N13: ='Cashflow Statement'!Q21 -> 0 | Q13: ='Cashflow Statement'!T21 -> 0 | T13: ='Cashflow Statement'!W21 -> 0 | W13: ='Cashflow Statement'!Z21 -> 0 | Z13: ='Cashflow Statement'!AC13 -> 100000000000 | AC13: ='Cashflow Statement'!AF21 -> 0 | AF13: ='Cashflow Statement'!AI21 -> 0 | AI13: ='Cashflow Statement'!AL21 -> 0 | AL13: ='Cashflow Statement'!AO21 -> 0 | AM13: =AM12 -> 2246.2729 | AN13: =AL13/AM13 -> 0
C14: TOTAL REVENUE | E14: =SUM(E10:E12) -> 2.0392755e+12 | G14: =SUM(G10:G12) -> 2.1406592e+09 | H14: =SUM(H10:H12) -> 0 | J14: =SUM(J10:J12) -> 0 | K14: =SUM(K10:K12) -> 30653209512 | M14: =SUM(M10:M12) -> 32177152 | N14: =SUM(N10:N12) -> 6.437174e+10 | P14: =SUM(P10:P12) -> 61429108 | Q14: =SUM(Q10:Q12) -> 1.2378754e+11 | S14: =SUM(S10:S12) -> 1.0738984e+08 | T14: =SUM(T10:T12) -> 1.7330256e+11 | V14: =SUM(V10:V12) -> 1.3667798e+08 | W14: =SUM(W10:W12) -> 2.2745961e+11 | Y14: =SUM(Y10:Y12) -> 1.6308168e+08 | Z14: =SUM(Z10:Z13) -> 3.3883259e+11 | AB14: =SUM(AB10:AB12) -> 1.5566888e+08 | AC14: =SUM(AC10:AC12) -> 2.5077422e+11 | AE14: =SUM(AE10:AE12) -> 1.4859302e+08 | AF14: =SUM(AF10:AF12) -> 2.6331293e+11 | AH14: =SUM(AH10:AH12) -> 1.4183879e+08 | AI14: =SUM(AI10:AI12) -> 2.7647857e+11 | AK14: =SUM(AK10:AK12) -> 1.3539158e+08 | AL14: =SUM(AL10:AL12) -> 3.903025e+11 | AN14: =SUM(AN10:AN12) -> 1.737556e+08
C17: Direct Cost
C19: Direct Labour/Wage Cost
C20: Drivers- Taxi | E20: =K20+N20+Q20+T20+W20+Z20+AC20+AF20+AI20+AL20 -> 5.3071624e+10 | F20: =F10 -> 952.639 | G20: =E20/F20 -> 55710110 | I20: =I10 -> 952.639 | J20: =H20/I20 -> 0 | K20: ='Cashflow Statement'!N38 -> 3330000000 | L20: =L10 -> 952.639 | M20: =K20/L20 -> 3495552.9 | N20: ='Cashflow Statement'!Q38 -> 3.663e+09 | O20: =O10 -> 1047.9029 | P20: =N20/O20 -> 3495552.9 | Q20: ='Cashflow Statement'!T38 -> 4.0293e+09 | R20: =R10 -> 1152.6932 | S20: =Q20/R20 -> 3495552.9 | T20: ='Cashflow Statement'!W38 -> 4.43223e+09 | U20: =U10 -> 1267.9625 | V20: =T20/U20 -> 3495552.9 | W20: ='Cashflow Statement'!Z38 -> 4.875453e+09 | X20: =X10 -> 1394.7588 | Y20: =W20/X20 -> 3495552.9 | Z20: ='Cashflow Statement'!AC38 -> 5.3629983e+09 | AA20: =AA10 -> 1534.2346 | AB20: =Z20/AA20 -> 3495552.9 | AC20: ='Cashflow Statement'!AF38 -> 5.8992981e+09 | AD20: =AD10 -> 1687.6581 | AE20: =AC20/AD20 -> 3495552.9 | AF20: ='Cashflow Statement'!AI38 -> 6.4892279e+09 | AG20: =AG10 -> 1856.4239 | AH20: =AF20/AG20 -> 3495552.9 | AI20: ='Cashflow Statement'!AL38 -> 7.1381507e+09 | AJ20: =AJ10 -> 2042.0663 | AK20: =AI20/AJ20 -> 3495552.9 | AL20: ='Cashflow Statement'!AO38 -> 7.8519658e+09 | AM20: =AM10 -> 2246.2729 | AN20: =AL20/AM20 -> 3495552.9
C21: Drivers- Bus | E21: =K21+N21+Q21+T21+W21+Z21+AC21+AF21+AI21+AL21 -> 1.0040577e+10 | F21: =F11 -> 952.639 | G21: =E21/F21 -> 10539751 | I21: =I11 -> 952.639 | J21: =H21/I21 -> 0 | K21: ='Cashflow Statement'!N39 -> 630000000 | L21: =L11 -> 952.639 | M21: =K21/L21 -> 661320.82 | N21: ='Cashflow Statement'!Q39 -> 693000000 | O21: =O11 -> 1047.9029 | P21: =N21/O21 -> 661320.82 | Q21: ='Cashflow Statement'!T39 -> 7.623e+08 | R21: =R11 -> 1152.6932 | S21: =Q21/R21 -> 661320.82 | T21: ='Cashflow Statement'!W39 -> 8.3853e+08 | U21: =U11 -> 1267.9625 | V21: =T21/U21 -> 661320.82 | W21: ='Cashflow Statement'!Z39 -> 9.22383e+08 | X21: =X11 -> 1394.7588 | Y21: =W21/X21 -> 661320.82 | Z21: ='Cashflow Statement'!AC39 -> 1.0146213e+09 | AA21: =AA11 -> 1534.2346 | AB21: =Z21/AA21 -> 661320.82 | AC21: ='Cashflow Statement'!AF39 -> 1.1160834e+09 | AD21: =AD11 -> 1687.6581 | AE21: =AC21/AD21 -> 661320.82 | AF21: ='Cashflow Statement'!AI39 -> 1.2276918e+09 | AG21: =AG11 -> 1856.4239 | AH21: =AF21/AG21 -> 661320.82 | AI21: ='Cashflow Statement'!AL39 -> 1.350461e+09 | AJ21: =AJ11 -> 2042.0663 | AK21: =AI21/AJ21 -> 661320.82 | AL21: ='Cashflow Statement'!AO39 -> 1.485507e+09 | AM21: =AM11 -> 2246.2729 | AN21: =AL21/AM21 -> 661320.82
C23: Repairs & Maintanance | E23: =K23+N23+Q23+T23+W23+Z23+AC23+AF23+AI23+AL23 -> 360000000 | F23: =F21 -> 952.639 | G23: =E23/F23 -> 377897.61 | I23: =I21 -> 952.639 | J23: =H23/I23 -> 0 | K23: ='Cashflow Statement'!N42 -> 360000000 | L23: =L21 -> 952.639 | M23: =K23/L23 -> 377897.61 | N23: ='Cashflow Statement'!Q42 -> 0 | O23: =O21 -> 1047.9029 | P23: =N23/O23 -> 0 | Q23: ='Cashflow Statement'!T42 -> 0 | R23: =R21 -> 1152.6932 | S23: =Q23/R23 -> 0 | T23: ='Cashflow Statement'!W42 -> 0 | U23: =U21 -> 1267.9625 | V23: =T23/U23 -> 0 | W23: ='Cashflow Statement'!Z42 -> 0 | X23: =X21 -> 1394.7588 | Y23: =W23/X23 -> 0 | Z23: ='Cashflow Statement'!AC42 -> 0 | AA23: =AA21 -> 1534.2346 | AB23: =Z23/AA23 -> 0 | AC23: ='Cashflow Statement'!AF42 -> 0 | AD23: =AD21 -> 1687.6581 | AE23: =AC23/AD23 -> 0 | AF23: ='Cashflow Statement'!AI42 -> 0 | AG23: =AG21 -> 1856.4239 | AH23: =AF23/AG23 -> 0 | AI23: ='Cashflow Statement'!AL42 -> 0 | AJ23: =AJ21 -> 2042.0663 | AK23: =AI23/AJ23 -> 0 | AL23: ='Cashflow Statement'!AO42 -> 0 | AM23: =AM21 -> 2246.2729 | AN23: =AL23/AM23 -> 0
C24: Energy and Power | E24: =K24+N24+Q24+T24+W24+Z24+AC24+AF24+AI24+AL24 -> 5299200000 | F24: =F23 -> 952.639 | G24: =E24/F24 -> 5562652.8 | I24: =I23 -> 952.639 | J24: =H24/I24 -> 0 | K24: ='Cashflow Statement'!N43 -> 5299200000 | L24: =L23 -> 952.639 | M24: =K24/L24 -> 5562652.8 | N24: ='Cashflow Statement'!Q43 -> 0 | O24: =O23 -> 1047.9029 | P24: =N24/O24 -> 0 | Q24: ='Cashflow Statement'!T43 -> 0 | R24: =R23 -> 1152.6932 | S24: =Q24/R24 -> 0 | T24: ='Cashflow Statement'!W43 -> 0 | U24: =U23 -> 1267.9625 | V24: =T24/U24 -> 0 | W24: ='Cashflow Statement'!Z43 -> 0 | X24: =X23 -> 1394.7588 | Y24: =W24/X24 -> 0 | Z24: ='Cashflow Statement'!AC43 -> 0 | AA24: =AA23 -> 1534.2346 | AB24: =Z24/AA24 -> 0 | AC24: ='Cashflow Statement'!AF43 -> 0 | AD24: =AD23 -> 1687.6581 | AE24: =AC24/AD24 -> 0 | AF24: ='Cashflow Statement'!AI43 -> 0 | AG24: =AG23 -> 1856.4239 | AH24: =AF24/AG24 -> 0 | AI24: ='Cashflow Statement'!AL43 -> 0 | AJ24: =AJ23 -> 2042.0663 | AK24: =AI24/AJ24 -> 0 | AL24: ='Cashflow Statement'!AO43 -> 0 | AM24: =AM23 -> 2246.2729 | AN24: =AL24/AM24 -> 0
C26: Depreciation & Amortisation- Fleets | E26: =K26+N26+Q26+T26+W26+Z26+AC26+AF26+AI26+AL26 -> 7.6985677e+11 | F26: =F24 -> 952.639 | G26: =E26/F26 -> 8.0813064e+08 | I26: =I24 -> 952.639 | J26: =H26/I26 -> 0 | K26: =CAPEX!C14 -> 1.6145783e+10 | L26: =L24 -> 952.639 | M26: =K26/L26 -> 16948480 | N26: =CAPEX!D14 -> 3.3906144e+10 | O26: =O24 -> 1047.9029 | P26: =N26/O26 -> 32356189 | Q26: =CAPEX!E14 -> 5.3442542e+10 | R26: =R24 -> 1152.6932 | S26: =Q26/R26 -> 46363197 | T26: =CAPEX!F14 -> 7.4932579e+10 | U26: =U24 -> 1267.9625 | V26: =T26/U26 -> 59096841 | W26: =CAPEX!G14 -> 9.857162e+10 | X26: =X24 -> 1394.7588 | Y26: =W26/X26 -> 70672881 | Z26: =CAPEX!H14 -> 9.857162e+10 | AA26: =AA24 -> 1534.2346 | AB26: =Z26/AA26 -> 64248074 | AC26: =CAPEX!I14 -> 9.857162e+10 | AD26: =AD24 -> 1687.6581 | AE26: =AC26/AD26 -> 58407340 | AF26: =CAPEX!J14 -> 9.857162e+10 | AG26: =AG24 -> 1856.4239 | AH26: =AF26/AG26 -> 53097582 | AI26: =CAPEX!K14 -> 9.857162e+10 | AJ26: =AJ24 -> 2042.0663 | AK26: =AI26/AJ26 -> 48270529 | AL26: =CAPEX!L14 -> 9.857162e+10 | AM26: =AM24 -> 2246.2729 | AN26: =AL26/AM26 -> 43882299
C27: Fleets Insurance | E27: =K27+N27+Q27+T27+W27+Z27+AC27+AF27+AI27+AL27 -> 7.6985677e+10 | F27: =F23 -> 952.639 | G27: =E27/F27 -> 80813064 | I27: =I23 -> 952.639 | J27: =H27/I27 -> 0 | K27: ='Cashflow Statement'!N46 -> 1.6145783e+09 | L27: =L23 -> 952.639 | M27: =K27/L27 -> 1694848 | N27: ='Cashflow Statement'!Q46 -> 3.3906144e+09 | O27: =O23 -> 1047.9029 | P27: =N27/O27 -> 3235618.9 | Q27: ='Cashflow Statement'!T46 -> 5.3442542e+09 | R27: =R23 -> 1152.6932 | S27: =Q27/R27 -> 4636319.7 | T27: ='Cashflow Statement'!W46 -> 7.4932579e+09 | U27: =U23 -> 1267.9625 | V27: =T27/U27 -> 5909684.1 | W27: ='Cashflow Statement'!Z46 -> 9.857162e+09 | X27: =X23 -> 1394.7588 | Y27: =W27/X27 -> 7067288.1 | Z27: ='Cashflow Statement'!AC46 -> 9.857162e+09 | AA27: =AA23 -> 1534.2346 | AB27: =Z27/AA27 -> 6424807.4 | AC27: ='Cashflow Statement'!AF46 -> 9.857162e+09 | AD27: =AD23 -> 1687.6581 | AE27: =AC27/AD27 -> 5840734 | AF27: ='Cashflow Statement'!AI46 -> 9.857162e+09 | AG27: =AG23 -> 1856.4239 | AH27: =AF27/AG27 -> 5309758.2 | AI27: ='Cashflow Statement'!AL46 -> 9.857162e+09 | AJ27: =AJ23 -> 2042.0663 | AK27: =AI27/AJ27 -> 4827052.9 | AL27: ='Cashflow Statement'!AO46 -> 9.857162e+09 | AM27: =AM23 -> 2246.2729 | AN27: =AL27/AM27 -> 4388229.9
C29: Total Direct Cost | E29: =SUM(E17:E28) -> 9.1561385e+11 | G29: =SUM(G17:G28) -> 9.6113412e+08 | H29: =SUM(H17:H28) -> 0 | J29: =SUM(J17:J28) -> 0 | K29: =SUM(K17:K28) -> 2.7379561e+10 | M29: =SUM(M17:M28) -> 28740752 | N29: =SUM(N17:N28) -> 4.1652759e+10 | P29: =SUM(P17:P28) -> 39748682 | Q29: =SUM(Q17:Q28) -> 6.3578396e+10 | S29: =SUM(S17:S28) -> 55156391 | T29: =SUM(T17:T28) -> 8.7696597e+10 | V29: =SUM(V17:V28) -> 69163399 | W29: =SUM(W17:W28) -> 1.1422662e+11 | Y29: =SUM(Y17:Y28) -> 81897043 | Z29: =SUM(Z17:Z28) -> 1.148064e+11 | AB29: =SUM(AB17:AB28) -> 74829755 | AC29: =SUM(AC17:AC28) -> 1.1544416e+11 | AE29: =SUM(AE17:AE28) -> 68404947 | AF29: =SUM(AF17:AF28) -> 1.161457e+11 | AH29: =SUM(AH17:AH28) -> 62564213 | AI29: =SUM(AI17:AI28) -> 1.1691739e+11 | AK29: =SUM(AK17:AK28) -> 57254455 | AL29: =SUM(AL17:AL28) -> 1.1776625e+11 | AN29: =SUM(AN17:AN28) -> 52427402
C31: Gross Profit | E31: =K31+N31+Q31+T31+W31+Z31+AC31+AF31+AI31+AL31 -> 1.2236616e+12 | G31: =G14-G29 -> 1.1795251e+09 | H31: =H14-H29 -> 0 | J31: =J14-J29 -> 0 | K31: =K14-K29 -> 3.2736482e+09 | M31: =M14-M29 -> 3436399.5 | N31: =N14-N29 -> 2.2718981e+10 | P31: =P14-P29 -> 21680426 | Q31: =Q14-Q29 -> 6.0209145e+10 | S31: =S14-S29 -> 52233453 | T31: =T14-T29 -> 8.5605961e+10 | V31: =V14-V29 -> 67514584 | W31: =W14-W29 -> 1.1323299e+11 | Y31: =Y14-Y29 -> 81184641 | Z31: =Z14-Z29 -> 2.2402619e+11 | AB31: =AB14-AB29 -> 80839125 | AC31: =AC14-AC29 -> 1.3533005e+11 | AE31: =AE14-AE29 -> 80188074 | AF31: =AF14-AF29 -> 1.4716723e+11 | AH31: =AH14-AH29 -> 79274580 | AI31: =AI14-AI29 -> 1.5956118e+11 | AK31: =AK14-AK29 -> 78137120 | AL31: =AL14-AL29 -> 2.7253625e+11 | AN31: =AN14-AN29 -> 1.213282e+08
C33: Operating & Maintenance Cost
C34: Personnel costs | E34: =K34+N34+Q34+T34+W34+Z34+AC34+AF34+AI34+AL34 -> 9.3712057e+09 | F34: =F10 -> 952.639 | G34: =E34/F34 -> 9837100.6 | I34: =I10 -> 952.639 | J34: =H34/I34 -> 0 | K34: ='Cashflow Statement'!N51 -> 588000000 | L34: =L10 -> 952.639 | M34: =K34/L34 -> 617232.76 | N34: ='Cashflow Statement'!Q51 -> 646800000 | O34: =O10 -> 1047.9029 | P34: =N34/O34 -> 617232.76 | Q34: ='Cashflow Statement'!T51 -> 711480000 | R34: =R10 -> 1152.6932 | S34: =Q34/R34 -> 617232.76 | T34: ='Cashflow Statement'!W51 -> 7.82628e+08 | U34: =U10 -> 1267.9625 | V34: =T34/U34 -> 617232.76 | W34: ='Cashflow Statement'!Z51 -> 8.608908e+08 | X34: =X10 -> 1394.7588 | Y34: =W34/X34 -> 617232.76 | Z34: ='Cashflow Statement'!AC51 -> 9.4697988e+08 | AA34: =AA10 -> 1534.2346 | AB34: =Z34/AA34 -> 617232.76 | AC34: ='Cashflow Statement'!AF51 -> 1.0416779e+09 | AD34: =AD10 -> 1687.6581 | AE34: =AC34/AD34 -> 617232.76 | AF34: ='Cashflow Statement'!AI51 -> 1.1458457e+09 | AG34: =AG10 -> 1856.4239 | AH34: =AF34/AG34 -> 617232.76 | AI34: ='Cashflow Statement'!AL51 -> 1.2604302e+09 | AJ34: =AJ10 -> 2042.0663 | AK34: =AI34/AJ34 -> 617232.76 | AL34: ='Cashflow Statement'!AO51 -> 1.3864732e+09 | AM34: =AM10 -> 2246.2729 | AN34: =AL34/AM34 -> 617232.76
N35: ='Cashflow Statement'!Q52 -> 0 | Q35: ='Cashflow Statement'!T52 -> 0 | T35: ='Cashflow Statement'!W52 -> 0 | W35: ='Cashflow Statement'!Z52 -> 0 | Z35: ='Cashflow Statement'!AC52 -> 0 | AC35: ='Cashflow Statement'!AF52 -> 0 | AF35: ='Cashflow Statement'!AI52 -> 0 | AI35: ='Cashflow Statement'!AL52 -> 0 | AL35: ='Cashflow Statement'!AO52 -> 0
C36: Other operating costs | N36: ='Cashflow Statement'!Q53 -> 0 | Q36: ='Cashflow Statement'!T53 -> 0 | T36: ='Cashflow Statement'!W53 -> 0 | W36: ='Cashflow Statement'!Z53 -> 0 | Z36: ='Cashflow Statement'!AC53 -> 0 | AC36: ='Cashflow Statement'!AF53 -> 0 | AF36: ='Cashflow Statement'!AI53 -> 0 | AI36: ='Cashflow Statement'!AL53 -> 0 | AL36: ='Cashflow Statement'!AO53 -> 0
C37: Admin Assets Insurance | D37: ='Cashflow Statement'!G54 -> 1.1 | E37: =K37+N37+Q37+T37+W37+Z37+AC37+AF37+AI37+AL37 -> 5500000 | F37: =F34 -> 952.639 | G37: =E37/F37 -> 5773.4357 | I37: =I34 -> 952.639 | J37: =H37/I37 -> 0 | K37: ='Cashflow Statement'!N54 -> 550000 | L37: =L34 -> 952.639 | M37: =K37/L37 -> 577.34357 | N37: ='Cashflow Statement'!Q54 -> 550000 | O37: =O34 -> 1047.9029 | P37: =N37/O37 -> 524.85779 | Q37: ='Cashflow Statement'!T54 -> 550000 | R37: =R34 -> 1152.6932 | S37: =Q37/R37 -> 477.14345 | T37: ='Cashflow Statement'!W54 -> 550000 | U37: =U34 -> 1267.9625 | V37: =T37/U37 -> 433.76677 | W37: ='Cashflow Statement'!Z54 -> 550000 | X37: =X34 -> 1394.7588 | Y37: =W37/X37 -> 394.33343 | Z37: ='Cashflow Statement'!AC54 -> 550000 | AA37: =AA34 -> 1534.2346 | AB37: =Z37/AA37 -> 358.48493 | AC37: ='Cashflow Statement'!AF54 -> 550000 | AD37: =AD34 -> 1687.6581 | AE37: =AC37/AD37 -> 325.89539 | AF37: ='Cashflow Statement'!AI54 -> 550000 | AG37: =AG34 -> 1856.4239 | AH37: =AF37/AG37 -> 296.26854 | AI37: ='Cashflow Statement'!AL54 -> 550000 | AJ37: =AJ34 -> 2042.0663 | AK37: =AI37/AJ37 -> 269.33504 | AL37: ='Cashflow Statement'!AO54 -> 550000 | AM37: =AM34 -> 2246.2729 | AN37: =AL37/AM37 -> 244.85003
C38: Marketing Expenses and Public Relation | D38: ='Cashflow Statement'!G55 -> 1.1 | E38: =K38+N38+Q38+T38+W38+Z38+AC38+AF38+AI38+AL38 -> 7.686641e+10 | F38: =F37 -> 952.639 | G38: =E38/F38 -> 80687869 | I38: =I37 -> 952.639 | J38: =H38/I38 -> 0 | K38: ='Cashflow Statement'!N55 -> 6.2196419e+08 | L38: =L37 -> 952.639 | M38: =K38/L38 -> 652885.5 | N38: ='Cashflow Statement'!Q55 -> 1.5792993e+09 | O38: =O37 -> 1047.9029 | P38: =N38/O38 -> 1507104.6 | Q38: ='Cashflow Statement'!T55 -> 3.7378076e+09 | R38: =R37 -> 1152.6932 | S38: =Q38/R38 -> 3242673.5 | T38: ='Cashflow Statement'!W55 -> 6.5985525e+09 | U38: =U37 -> 1267.9625 | V38: =T38/U38 -> 5204059.6 | W38: ='Cashflow Statement'!Z55 -> 1.0095914e+10 | X38: =X37 -> 1394.7588 | Y38: =W38/X38 -> 7238466.1 | Z38: ='Cashflow Statement'!AC55 -> 1.5428676e+10 | AA38: =AA37 -> 1534.2346 | AB38: =Z38/AA38 -> 10056269 | AC38: ='Cashflow Statement'!AF55 -> 1.3340302e+10 | AD38: =AD37 -> 1687.6581 | AE38: =AC38/AD38 -> 7904623.6 | AF38: ='Cashflow Statement'!AI55 -> 1.0432785e+10 | AG38: =AG37 -> 1856.4239 | AH38: =AF38/AG38 -> 5619828.9 | AI38: ='Cashflow Statement'!AL55 -> 7.944351e+09 | AJ38: =AJ37 -> 2042.0663 | AK38: =AI38/AJ38 -> 3890349.2 | AL38: ='Cashflow Statement'!AO55 -> 7.0867588e+09 | AM38: =AM37 -> 2246.2729 | AN38: =AL38/AM38 -> 3154896.6
C39: Pension Contribution | D39: ='Cashflow Statement'!G56 -> 1.1 | E39: =K39+N39+Q39+T39+W39+Z39+AC39+AF39+AI39+AL39 -> 5.7986726e+09 | F39: =F38 -> 952.639 | G39: =E39/F39 -> 6086956.9 | I39: =I38 -> 952.639 | J39: =H39/I39 -> 0 | K39: ='Cashflow Statement'!N56 -> 363840000 | L39: =L38 -> 952.639 | M39: =K39/L39 -> 381928.52 | N39: ='Cashflow Statement'!Q56 -> 400224000 | O39: =O38 -> 1047.9029 | P39: =N39/O39 -> 381928.52 | Q39: ='Cashflow Statement'!T56 -> 4.402464e+08 | R39: =R38 -> 1152.6932 | S39: =Q39/R39 -> 381928.52 | T39: ='Cashflow Statement'!W56 -> 4.8427104e+08 | U39: =U38 -> 1267.9625 | V39: =T39/U39 -> 381928.52 | W39: ='Cashflow Statement'!Z56 -> 5.3269814e+08 | X39: =X38 -> 1394.7588 | Y39: =W39/X39 -> 381928.52 | Z39: ='Cashflow Statement'!AC56 -> 5.8596796e+08 | AA39: =AA38 -> 1534.2346 | AB39: =Z39/AA39 -> 381928.52 | AC39: ='Cashflow Statement'!AF56 -> 6.4456475e+08 | AD39: =AD38 -> 1687.6581 | AE39: =AC39/AD39 -> 381928.52 | AF39: ='Cashflow Statement'!AI56 -> 7.0902123e+08 | AG39: =AG38 -> 1856.4239 | AH39: =AF39/AG39 -> 381928.52 | AI39: ='Cashflow Statement'!AL56 -> 7.7992335e+08 | AJ39: =AJ38 -> 2042.0663 | AK39: =AI39/AJ39 -> 381928.52 | AL39: ='Cashflow Statement'!AO56 -> 8.5791569e+08 | AM39: =AM38 -> 2246.2729 | AN39: =AL39/AM39 -> 381928.52
C40: Group Life | D40: ='Cashflow Statement'!G57 -> 1.1 | E40: =K40+N40+Q40+T40+W40+Z40+AC40+AF40+AI40+AL40 -> 7.2483407e+08 | F40: =F39 -> 952.639 | G40: =E40/F40 -> 760869.62 | I40: =I39 -> 952.639 | J40: =H40/I40 -> 0 | K40: ='Cashflow Statement'!N57 -> 45480000 | L40: =L39 -> 952.639 | M40: =K40/L40 -> 47741.065 | N40: ='Cashflow Statement'!Q57 -> 50028000 | O40: =O39 -> 1047.9029 | P40: =N40/O40 -> 47741.065 | Q40: ='Cashflow Statement'!T57 -> 55030800 | R40: =R39 -> 1152.6932 | S40: =Q40/R40 -> 47741.065 | T40: ='Cashflow Statement'!W57 -> 60533880 | U40: =U39 -> 1267.9625 | V40: =T40/U40 -> 47741.065 | W40: ='Cashflow Statement'!Z57 -> 66587268 | X40: =X39 -> 1394.7588 | Y40: =W40/X40 -> 47741.065 | Z40: ='Cashflow Statement'!AC57 -> 73245995 | AA40: =AA39 -> 1534.2346 | AB40: =Z40/AA40 -> 47741.065 | AC40: ='Cashflow Statement'!AF57 -> 80570594 | AD40: =AD39 -> 1687.6581 | AE40: =AC40/AD40 -> 47741.065 | AF40: ='Cashflow Statement'!AI57 -> 88627654 | AG40: =AG39 -> 1856.4239 | AH40: =AF40/AG40 -> 47741.065 | AI40: ='Cashflow Statement'!AL57 -> 97490419 | AJ40: =AJ39 -> 2042.0663 | AK40: =AI40/AJ40 -> 47741.065 | AL40: ='Cashflow Statement'!AO57 -> 1.0723946e+08 | AM40: =AM39 -> 2246.2729 | AN40: =AL40/AM40 -> 47741.065
C41: NSITF | D41: ='Cashflow Statement'!G58 -> 1.1 | E41: =K41+N41+Q41+T41+W41+Z41+AC41+AF41+AI41+AL41 -> 7.2483407e+08 | F41: =F39 -> 952.639 | G41: =E41/F41 -> 760869.62 | I41: =I39 -> 952.639 | J41: =H41/I41 -> 0 | K41: ='Cashflow Statement'!N58 -> 45480000 | L41: =L39 -> 952.639 | M41: =K41/L41 -> 47741.065 | N41: ='Cashflow Statement'!Q58 -> 50028000 | O41: =O39 -> 1047.9029 | P41: =N41/O41 -> 47741.065 | Q41: ='Cashflow Statement'!T58 -> 55030800 | R41: =R39 -> 1152.6932 | S41: =Q41/R41 -> 47741.065 | T41: ='Cashflow Statement'!W58 -> 60533880 | U41: =U39 -> 1267.9625 | V41: =T41/U41 -> 47741.065 | W41: ='Cashflow Statement'!Z58 -> 66587268 | X41: =X39 -> 1394.7588 | Y41: =W41/X41 -> 47741.065 | Z41: ='Cashflow Statement'!AC58 -> 73245995 | AA41: =AA39 -> 1534.2346 | AB41: =Z41/AA41 -> 47741.065 | AC41: ='Cashflow Statement'!AF58 -> 80570594 | AD41: =AD39 -> 1687.6581 | AE41: =AC41/AD41 -> 47741.065 | AF41: ='Cashflow Statement'!AI58 -> 88627654 | AG41: =AG39 -> 1856.4239 | AH41: =AF41/AG41 -> 47741.065 | AI41: ='Cashflow Statement'!AL58 -> 97490419 | AJ41: =AJ39 -> 2042.0663 | AK41: =AI41/AJ41 -> 47741.065 | AL41: ='Cashflow Statement'!AO58 -> 1.0723946e+08 | AM41: =AM39 -> 2246.2729 | AN41: =AL41/AM41 -> 47741.065
C42: NHIS | D42: ='Cashflow Statement'!G59 -> 1.1 | E42: =K42+N42+Q42+T42+W42+Z42+AC42+AF42+AI42+AL42 -> 1.8120852e+09 | F42: =F39 -> 952.639 | G42: =E42/F42 -> 1902174 | I42: =I39 -> 952.639 | J42: =H42/I42 -> 0 | K42: ='Cashflow Statement'!N59 -> 113700000 | L42: =L39 -> 952.639 | M42: =K42/L42 -> 119352.66 | N42: ='Cashflow Statement'!Q59 -> 125070000 | O42: =O39 -> 1047.9029 | P42: =N42/O42 -> 119352.66 | Q42: ='Cashflow Statement'!T59 -> 1.37577e+08 | R42: =R39 -> 1152.6932 | S42: =Q42/R42 -> 119352.66 | T42: ='Cashflow Statement'!W59 -> 1.513347e+08 | U42: =U39 -> 1267.9625 | V42: =T42/U42 -> 119352.66 | W42: ='Cashflow Statement'!Z59 -> 1.6646817e+08 | X42: =X39 -> 1394.7588 | Y42: =W42/X42 -> 119352.66 | Z42: ='Cashflow Statement'!AC59 -> 1.8311499e+08 | AA42: =AA39 -> 1534.2346 | AB42: =Z42/AA42 -> 119352.66 | AC42: ='Cashflow Statement'!AF59 -> 2.0142649e+08 | AD42: =AD39 -> 1687.6581 | AE42: =AC42/AD42 -> 119352.66 | AF42: ='Cashflow Statement'!AI59 -> 2.2156913e+08 | AG42: =AG39 -> 1856.4239 | AH42: =AF42/AG42 -> 119352.66 | AI42: ='Cashflow Statement'!AL59 -> 2.4372605e+08 | AJ42: =AJ39 -> 2042.0663 | AK42: =AI42/AJ42 -> 119352.66 | AL42: ='Cashflow Statement'!AO59 -> 2.6809865e+08 | AM42: =AM39 -> 2246.2729 | AN42: =AL42/AM42 -> 119352.66
C43: Board Expenses | D43: ='Cashflow Statement'!G60 -> 1.1 | E43: =K43+N43+Q43+T43+W43+Z43+AC43+AF43+AI43+AL43 -> 1.5937425e+10 | F43: =F39 -> 952.639 | G43: =E43/F43 -> 16729763 | I43: =I39 -> 952.639 | J43: =H43/I43 -> 0 | K43: ='Cashflow Statement'!N60 -> 1000000000 | L43: =L39 -> 952.639 | M43: =K43/L43 -> 1049715.6 | N43: ='Cashflow Statement'!Q60 -> 1100000000 | O43: =O39 -> 1047.9029 | P43: =N43/O43 -> 1049715.6 | Q43: ='Cashflow Statement'!T60 -> 1210000000 | R43: =R39 -> 1152.6932 | S43: =Q43/R43 -> 1049715.6 | T43: ='Cashflow Statement'!W60 -> 1331000000 | U43: =U39 -> 1267.9625 | V43: =T43/U43 -> 1049715.6 | W43: ='Cashflow Statement'!Z60 -> 1464100000 | X43: =X39 -> 1394.7588 | Y43: =W43/X43 -> 1049715.6 | Z43: ='Cashflow Statement'!AC60 -> 1.61051e+09 | AA43: =AA39 -> 1534.2346 | AB43: =Z43/AA43 -> 1049715.6 | AC43: ='Cashflow Statement'!AF60 -> 1.771561e+09 | AD43: =AD39 -> 1687.6581 | AE43: =AC43/AD43 -> 1049715.6 | AF43: ='Cashflow Statement'!AI60 -> 1.9487171e+09 | AG43: =AG39 -> 1856.4239 | AH43: =AF43/AG43 -> 1049715.6 | AI43: ='Cashflow Statement'!AL60 -> 2.1435888e+09 | AJ43: =AJ39 -> 2042.0663 | AK43: =AI43/AJ43 -> 1049715.6 | AL43: ='Cashflow Statement'!AO60 -> 2.3579477e+09 | AM43: =AM39 -> 2246.2729 | AN43: =AL43/AM43 -> 1049715.6
C44: Printing & Stationary | D44: ='Cashflow Statement'!G61 -> 1.1 | E44: =K44+N44+Q44+T44+W44+Z44+AC44+AF44+AI44+AL44 -> 1.5937425e+08 | F44: =F43 -> 952.639 | G44: =E44/F44 -> 167297.63 | I44: =I43 -> 952.639 | J44: =H44/I44 -> 0 | K44: ='Cashflow Statement'!N61 -> 10000000 | L44: =L43 -> 952.639 | M44: =K44/L44 -> 10497.156 | N44: ='Cashflow Statement'!Q61 -> 11000000 | O44: =O43 -> 1047.9029 | P44: =N44/O44 -> 10497.156 | Q44: ='Cashflow Statement'!T61 -> 12100000 | R44: =R43 -> 1152.6932 | S44: =Q44/R44 -> 10497.156 | T44: ='Cashflow Statement'!W61 -> 13310000 | U44: =U43 -> 1267.9625 | V44: =T44/U44 -> 10497.156 | W44: ='Cashflow Statement'!Z61 -> 14641000 | X44: =X43 -> 1394.7588 | Y44: =W44/X44 -> 10497.156 | Z44: ='Cashflow Statement'!AC61 -> 16105100 | AA44: =AA43 -> 1534.2346 | AB44: =Z44/AA44 -> 10497.156 | AC44: ='Cashflow Statement'!AF61 -> 17715610 | AD44: =AD43 -> 1687.6581 | AE44: =AC44/AD44 -> 10497.156 | AF44: ='Cashflow Statement'!AI61 -> 19487171 | AG44: =AG43 -> 1856.4239 | AH44: =AF44/AG44 -> 10497.156 | AI44: ='Cashflow Statement'!AL61 -> 21435888 | AJ44: =AJ43 -> 2042.0663 | AK44: =AI44/AJ44 -> 10497.156 | AL44: ='Cashflow Statement'!AO61 -> 23579477 | AM44: =AM43 -> 2246.2729 | AN44: =AL44/AM44 -> 10497.156
C45: Vehicle Maintenance | D45: ='Cashflow Statement'!G62 -> 1.1 | E45: =K45+N45+Q45+T45+W45+Z45+AC45+AF45+AI45+AL45 -> 264960000 | F45: =F44 -> 952.639 | G45: =E45/F45 -> 278132.64 | I45: =I44 -> 952.639 | J45: =H45/I45 -> 0 | K45: ='Cashflow Statement'!N62 -> 264960000 | L45: =L44 -> 952.639 | M45: =K45/L45 -> 278132.64 | N45: ='Cashflow Statement'!Q62 -> 0 | O45: =O44 -> 1047.9029 | P45: =N45/O45 -> 0 | Q45: ='Cashflow Statement'!T62 -> 0 | R45: =R44 -> 1152.6932 | S45: =Q45/R45 -> 0 | T45: ='Cashflow Statement'!W62 -> 0 | U45: =U44 -> 1267.9625 | V45: =T45/U45 -> 0 | W45: ='Cashflow Statement'!Z62 -> 0 | X45: =X44 -> 1394.7588 | Y45: =W45/X45 -> 0 | Z45: ='Cashflow Statement'!AC62 -> 0 | AA45: =AA44 -> 1534.2346 | AB45: =Z45/AA45 -> 0 | AC45: ='Cashflow Statement'!AF62 -> 0 | AD45: =AD44 -> 1687.6581 | AE45: =AC45/AD45 -> 0 | AF45: ='Cashflow Statement'!AI62 -> 0 | AG45: =AG44 -> 1856.4239 | AH45: =AF45/AG45 -> 0 | AI45: ='Cashflow Statement'!AL62 -> 0 | AJ45: =AJ44 -> 2042.0663 | AK45: =AI45/AJ45 -> 0 | AL45: ='Cashflow Statement'!AO62 -> 0 | AM45: =AM44 -> 2246.2729 | AN45: =AL45/AM45 -> 0
C46: Rent | D46: ='Cashflow Statement'!G63 -> 1.1 | E46: =K46+N46+Q46+T46+W46+Z46+AC46+AF46+AI46+AL46 -> 7.9687123e+08 | F46: =F45 -> 952.639 | G46: =E46/F46 -> 836488.15 | I46: =I45 -> 952.639 | J46: =H46/I46 -> 0 | K46: ='Cashflow Statement'!N63 -> 50000000 | L46: =L45 -> 952.639 | M46: =K46/L46 -> 52485.779 | N46: ='Cashflow Statement'!Q63 -> 55000000 | O46: =O45 -> 1047.9029 | P46: =N46/O46 -> 52485.779 | Q46: ='Cashflow Statement'!T63 -> 60500000 | R46: =R45 -> 1152.6932 | S46: =Q46/R46 -> 52485.779 | T46: ='Cashflow Statement'!W63 -> 66550000 | U46: =U45 -> 1267.9625 | V46: =T46/U46 -> 52485.779 | W46: ='Cashflow Statement'!Z63 -> 73205000 | X46: =X45 -> 1394.7588 | Y46: =W46/X46 -> 52485.779 | Z46: ='Cashflow Statement'!AC63 -> 80525500 | AA46: =AA45 -> 1534.2346 | AB46: =Z46/AA46 -> 52485.779 | AC46: ='Cashflow Statement'!AF63 -> 88578050 | AD46: =AD45 -> 1687.6581 | AE46: =AC46/AD46 -> 52485.779 | AF46: ='Cashflow Statement'!AI63 -> 97435855 | AG46: =AG45 -> 1856.4239 | AH46: =AF46/AG46 -> 52485.779 | AI46: ='Cashflow Statement'!AL63 -> 1.0717944e+08 | AJ46: =AJ45 -> 2042.0663 | AK46: =AI46/AJ46 -> 52485.779 | AL46: ='Cashflow Statement'!AO63 -> 1.1789738e+08 | AM46: =AM45 -> 2246.2729 | AN46: =AL46/AM46 -> 52485.779
C47: Maintenance - Buildings | D47: ='Cashflow Statement'!G64 -> 1.1 | E47: =K47+N47+Q47+T47+W47+Z47+AC47+AF47+AI47+AL47 -> 1.5937425e+08 | F47: =F45 -> 952.639 | G47: =E47/F47 -> 167297.63 | I47: =I45 -> 952.639 | J47: =H47/I47 -> 0 | K47: ='Cashflow Statement'!N64 -> 10000000 | L47: =L45 -> 952.639 | M47: =K47/L47 -> 10497.156 | N47: ='Cashflow Statement'!Q64 -> 11000000 | O47: =O45 -> 1047.9029 | P47: =N47/O47 -> 10497.156 | Q47: ='Cashflow Statement'!T64 -> 12100000 | R47: =R45 -> 1152.6932 | S47: =Q47/R47 -> 10497.156 | T47: ='Cashflow Statement'!W64 -> 13310000 | U47: =U45 -> 1267.9625 | V47: =T47/U47 -> 10497.156 | W47: ='Cashflow Statement'!Z64 -> 14641000 | X47: =X45 -> 1394.7588 | Y47: =W47/X47 -> 10497.156 | Z47: ='Cashflow Statement'!AC64 -> 16105100 | AA47: =AA45 -> 1534.2346 | AB47: =Z47/AA47 -> 10497.156 | AC47: ='Cashflow Statement'!AF64 -> 17715610 | AD47: =AD45 -> 1687.6581 | AE47: =AC47/AD47 -> 10497.156 | AF47: ='Cashflow Statement'!AI64 -> 19487171 | AG47: =AG45 -> 1856.4239 | AH47: =AF47/AG47 -> 10497.156 | AI47: ='Cashflow Statement'!AL64 -> 21435888 | AJ47: =AJ45 -> 2042.0663 | AK47: =AI47/AJ47 -> 10497.156 | AL47: ='Cashflow Statement'!AO64 -> 23579477 | AM47: =AM45 -> 2246.2729 | AN47: =AL47/AM47 -> 10497.156
C48: Maintenance - Equipment | D48: ='Cashflow Statement'!G65 -> 1.1 | E48: =K48+N48+Q48+T48+W48+Z48+AC48+AF48+AI48+AL48 -> 8765583.5 | F48: =F47 -> 952.639 | G48: =E48/F48 -> 9201.3696 | I48: =I47 -> 952.639 | J48: =H48/I48 -> 0 | K48: ='Cashflow Statement'!N65 -> 550000 | L48: =L47 -> 952.639 | M48: =K48/L48 -> 577.34357 | N48: ='Cashflow Statement'!Q65 -> 605000 | O48: =O47 -> 1047.9029 | P48: =N48/O48 -> 577.34357 | Q48: ='Cashflow Statement'!T65 -> 665500 | R48: =R47 -> 1152.6932 | S48: =Q48/R48 -> 577.34357 | T48: ='Cashflow Statement'!W65 -> 732050 | U48: =U47 -> 1267.9625 | V48: =T48/U48 -> 577.34357 | W48: ='Cashflow Statement'!Z65 -> 805255 | X48: =X47 -> 1394.7588 | Y48: =W48/X48 -> 577.34357 | Z48: ='Cashflow Statement'!AC65 -> 885780.5 | AA48: =AA47 -> 1534.2346 | AB48: =Z48/AA48 -> 577.34357 | AC48: ='Cashflow Statement'!AF65 -> 974358.55 | AD48: =AD47 -> 1687.6581 | AE48: =AC48/AD48 -> 577.34357 | AF48: ='Cashflow Statement'!AI65 -> 1071794.4 | AG48: =AG47 -> 1856.4239 | AH48: =AF48/AG48 -> 577.34357 | AI48: ='Cashflow Statement'!AL65 -> 1178973.8 | AJ48: =AJ47 -> 2042.0663 | AK48: =AI48/AJ48 -> 577.34357 | AL48: ='Cashflow Statement'!AO65 -> 1296871.2 | AM48: =AM47 -> 2246.2729 | AN48: =AL48/AM48 -> 577.34357
C49: Postage & Communication | D49: ='Cashflow Statement'!G66 -> 1.1 | E49: =K49+N49+Q49+T49+W49+Z49+AC49+AF49+AI49+AL49 -> 1.4496681e+09 | F49: =F48 -> 952.639 | G49: =E49/F49 -> 1521739.2 | I49: =I48 -> 952.639 | J49: =H49/I49 -> 0 | K49: ='Cashflow Statement'!N66 -> 90960000 | L49: =L48 -> 952.639 | M49: =K49/L49 -> 95482.129 | N49: ='Cashflow Statement'!Q66 -> 1.00056e+08 | O49: =O48 -> 1047.9029 | P49: =N49/O49 -> 95482.129 | Q49: ='Cashflow Statement'!T66 -> 1.100616e+08 | R49: =R48 -> 1152.6932 | S49: =Q49/R49 -> 95482.129 | T49: ='Cashflow Statement'!W66 -> 1.2106776e+08 | U49: =U48 -> 1267.9625 | V49: =T49/U49 -> 95482.129 | W49: ='Cashflow Statement'!Z66 -> 1.3317454e+08 | X49: =X48 -> 1394.7588 | Y49: =W49/X49 -> 95482.129 | Z49: ='Cashflow Statement'!AC66 -> 1.4649199e+08 | AA49: =AA48 -> 1534.2346 | AB49: =Z49/AA49 -> 95482.129 | AC49: ='Cashflow Statement'!AF66 -> 1.6114119e+08 | AD49: =AD48 -> 1687.6581 | AE49: =AC49/AD49 -> 95482.129 | AF49: ='Cashflow Statement'!AI66 -> 1.7725531e+08 | AG49: =AG48 -> 1856.4239 | AH49: =AF49/AG49 -> 95482.129 | AI49: ='Cashflow Statement'!AL66 -> 1.9498084e+08 | AJ49: =AJ48 -> 2042.0663 | AK49: =AI49/AJ49 -> 95482.129 | AL49: ='Cashflow Statement'!AO66 -> 2.1447892e+08 | AM49: =AM48 -> 2246.2729 | AN49: =AL49/AM49 -> 95482.129
C50: Human Capital Development (ITF Inclusive) | D50: ='Cashflow Statement'!G67 -> 1.1 | E50: =K50+N50+Q50+T50+W50+Z50+AC50+AF50+AI50+AL50 -> 1.4496681e+09 | F50: =F49 -> 952.639 | G50: =E50/F50 -> 1521739.2 | I50: =I49 -> 952.639 | J50: =H50/I50 -> 0 | K50: ='Cashflow Statement'!N67 -> 90960000 | L50: =L49 -> 952.639 | M50: =K50/L50 -> 95482.129 | N50: ='Cashflow Statement'!Q67 -> 1.00056e+08 | O50: =O49 -> 1047.9029 | P50: =N50/O50 -> 95482.129 | Q50: ='Cashflow Statement'!T67 -> 1.100616e+08 | R50: =R49 -> 1152.6932 | S50: =Q50/R50 -> 95482.129 | T50: ='Cashflow Statement'!W67 -> 1.2106776e+08 | U50: =U49 -> 1267.9625 | V50: =T50/U50 -> 95482.129 | W50: ='Cashflow Statement'!Z67 -> 1.3317454e+08 | X50: =X49 -> 1394.7588 | Y50: =W50/X50 -> 95482.129 | Z50: ='Cashflow Statement'!AC67 -> 1.4649199e+08 | AA50: =AA49 -> 1534.2346 | AB50: =Z50/AA50 -> 95482.129 | AC50: ='Cashflow Statement'!AF67 -> 1.6114119e+08 | AD50: =AD49 -> 1687.6581 | AE50: =AC50/AD50 -> 95482.129 | AF50: ='Cashflow Statement'!AI67 -> 1.7725531e+08 | AG50: =AG49 -> 1856.4239 | AH50: =AF50/AG50 -> 95482.129 | AI50: ='Cashflow Statement'!AL67 -> 1.9498084e+08 | AJ50: =AJ49 -> 2042.0663 | AK50: =AI50/AJ50 -> 95482.129 | AL50: ='Cashflow Statement'!AO67 -> 2.1447892e+08 | AM50: =AM49 -> 2246.2729 | AN50: =AL50/AM50 -> 95482.129
...

Sheet Cashflow Statement
C2: Projected Cash Flow Statement
C3: Enhancement of Public Transportation in the FCT
K5: Construction/ Deployment Period | N5: 1 | Q5: =N5+1 -> 2 | T5: =Q5+1 -> 3 | W5: =T5+1 -> 4 | Z5: =W5+1 -> 5 | AC5: =Z5+1 -> 6 | AF5: =AC5+1 -> 7 | AI5: =AF5+1 -> 8 | AL5: =AI5+1 -> 9 | AO5: =AL5+1 -> 10
F6: Rate | H6: Cummulative | K6: 2023 | N6: 45657 | Q6: 46022 | T6: 46387 | W6: 46752 | Z6: 47118 | AC6: 47483 | AF6: 47848 | AI6: 48213 | AL6: 48579 | AO6: 48944
D7: Basis | E7: Rate | G7: Annual Growth Factor | H7: NGN | J7: USD | K7: NGN | M7: USD | N7: NGN | P7: USD | Q7: NGN | S7: USD | T7: NGN | V7: USD | W7: NGN | Y7: USD | Z7: NGN | AB7: USD | AC7: NGN | AE7: USD | AF7: NGN | AH7: USD | AI7: NGN | AK7: USD | AL7: NGN | AN7: USD | AO7: NGN | AQ7: USD
C8: Beginning Cash Balance | F8: ='Parameters and Summary'!E70 -> 952.639 | H8: =K8 -> 0 | I8: ='Exchange Rate growth '!D6 -> 952.639 | J8: =M8 -> 0 | L8: ='Exchange Rate growth '!D6 -> 952.639 | M8: =K8/L8 -> 0 | N8: =K91 -> 445000000 | O8: ='Exchange Rate growth '!D6 -> 952.639 | P8: =N8/O8 -> 467123.43 | Q8: =N91 -> 1.4593225e+10 | R8: ='Exchange Rate growth '!E6 -> 1047.9029 | S8: =Q8/R8 -> 13926123 | T8: =Q91 -> 6.3102839e+10 | U8: ='Exchange Rate growth '!F6 -> 1152.6932 | V8: =T8/U8 -> 54743829 | W8: =T91 -> 1.5662507e+11 | X8: ='Exchange Rate growth '!G6 -> 1267.9625 | Y8: =W8/X8 -> 1.23525e+08 | Z8: =W91 -> 2.773361e+11 | AA8: ='Exchange Rate growth '!H6 -> 1394.7588 | AB8: =Z8/AA8 -> 1.9884162e+08 | AC8: =Z91 -> 4.3260122e+11 | AD8: ='Exchange Rate growth '!I6 -> 1534.2346 | AE8: =AC8/AD8 -> 2.8196549e+08 | AF8: =AC91 -> 4.1624089e+11 | AG8: ='Exchange Rate growth '!J6 -> 1687.6581 | AH8: =AF8/AG8 -> 2.4663816e+08 | AI8: =AF91 -> 2.583263e+11 | AJ8: ='Exchange Rate growth '!K6 -> 1856.4239 | AK8: =AI8/AJ8 -> 1.3915265e+08 | AL8: =AI91 -> 1.2073898e+11 | AM8: ='Exchange Rate growth '!L6 -> 2042.0663 | AN8: =AL8/AM8 -> 59125884 | AO8: =AL91 -> -3.5964561e+10 | AP8: ='Exchange Rate growth '!M6 -> 2246.2729 | AQ8: =AO8/AP8 -> -16010771
C10: CASH INFLOWS
C11: ='[2]Investment Financing'!C6 -> Equity Financing | F11: =F8 -> 952.639 | H11: =K11+N11+Q11+T11+W11+Z11+AC11+AF11+AI11+AL11+AO11 -> 500000000 | I11: =I8 -> 952.639 | J11: =M11+P11+S11+V11+Y11+AB11+AE11+AH11+AK11+AN11+AQ11 -> 524857.79 | K11: 500000000 | L11: =L8 -> 952.639 | M11: =K11/L11 -> 524857.79 | O11: =O8 -> 952.639 | P11: =N11/O11 -> 0 | R11: =R8 -> 1047.9029 | S11: =Q11/R11 -> 0 | U11: =U8 -> 1152.6932 | V11: =T11/U11 -> 0 | X11: =X8 -> 1267.9625 | Y11: =W11/X11 -> 0 | AA11: =AA8 -> 1394.7588 | AB11: =Z11/AA11 -> 0 | AD11: =AD8 -> 1534.2346 | AE11: =AC11/AD11 -> 0 | AG11: =AG8 -> 1687.6581 | AH11: =AF11/AG11 -> 0 | AJ11: =AJ8 -> 1856.4239 | AK11: =AI11/AJ11 -> 0 | AM11: =AM8 -> 2042.0663 | AN11: =AL11/AM11 -> 0 | AP11: =AP8 -> 2246.2729 | AQ11: =AO11/AP11 -> 0
I12: =D12 -> 0
C13: Bonds | F13: =F12 -> 0 | H13: =K13+N13+Q13+T13+W13+Z13+AC13+AF13+AI13+AL13+AO13 -> 100000000000 | I13: =I12 -> 0 | J13: =M13+P13+S13+V13+Y13+AB13+AE13+AH13+AK13+AN13+AQ13 -> #DIV/0! | L13: =L12 -> 0 | M13: =K13/L13 -> #DIV/0! | N13: ='Revenue Schedule'!AE60 -> 0 | O13: =O12 -> 0 | P13: =N13/O13 -> #DIV/0! | Q13: ='Revenue Schedule'!BD60 -> 0 | R13: =R12 -> 0 | S13: =Q13/R13 -> #DIV/0! | T13: ='Revenue Schedule'!CC60 -> 0 | U13: =U12 -> 0 | V13: =T13/U13 -> #DIV/0! | W13: ='Revenue Schedule'!DB60 -> 0 | X13: =X12 -> 0 | Y13: =W13/X13 -> #DIV/0! | Z13: ='Revenue Schedule'!EA60 -> 0 | AA13: =AA11 -> 1394.7588 | AB13: =Z13/AA13 -> 0 | AC13: 100000000000 | AD13: =AD11 -> 1534.2346 | AE13: =AC13/AD13 -> 65179079 | AF13: ='Revenue Schedule'!FY60 -> 0 | AG13: =AG11 -> 1687.6581 | AH13: =AF13/AG13 -> 0 | AI13: ='Revenue Schedule'!GX60 -> 0 | AJ13: =AJ11 -> 1856.4239 | AK13: =AI13/AJ13 -> 0 | AL13: ='Revenue Schedule'!HW60 -> 0 | AM13: =AM11 -> 2042.0663 | AN13: =AL13/AM13 -> 0 | AO13: ='Revenue Schedule'!IV60 -> 0 | AP13: =AP11 -> 2246.2729 | AQ13: =AO13/AP13 -> 0
AC14: 0
C15: Transportation Fare
C16: Taxi | F16: =F11 -> 952.639 | H16: =K16+N16+Q16+T16+W16+Z16+AC16+AF16+AI16+AL16+AO16 -> 7.8514975e+11 | I16: =I11 -> 952.639 | J16: =M16+P16+S16+V16+Y16+AB16+AE16+AH16+AK16+AN16+AQ16 -> 4.9352173e+08 | L16: =L11 -> 952.639 | M16: =K16/L16 -> 0 | N16: ='Revenue Schedule'!AE31 -> 14990400000 | O16: =O11 -> 952.639 | P16: =N16/O16 -> 15735656 | Q16: ='Revenue Schedule'!BD31 -> 31479840000 | R16: =R11 -> 1047.9029 | S16: =Q16/R16 -> 30040799 | T16: ='Revenue Schedule'!CC31 -> 49580748000 | U16: =U11 -> 1152.6932 | V16: =T16/U16 -> 43012962 | W16: ='Revenue Schedule'!DB31 -> 69413047200 | X16: =X11 -> 1267.9625 | Y16: =W16/X16 -> 54743769 | Z16: ='Revenue Schedule'!EA31 -> 91104624450 | AA16: =AA11 -> 1394.7588 | AB16: =Z16/AA16 -> 65319270 | AC16: ='Revenue Schedule'!EZ31 -> 9.5659856e+10 | AD16: =AD11 -> 1534.2346 | AE16: =AC16/AD16 -> 62350213 | AF16: ='Revenue Schedule'!FY31 -> 1.0044285e+11 | AG16: =AG11 -> 1687.6581 | AH16: =AF16/AG16 -> 59516112 | AI16: ='Revenue Schedule'!GX31 -> 1.0546499e+11 | AJ16: =AJ11 -> 1856.4239 | AK16: =AI16/AJ16 -> 56810834 | AL16: ='Revenue Schedule'!HW31 -> 1.1073824e+11 | AM16: =AM11 -> 2042.0663 | AN16: =AL16/AM16 -> 54228524 | AO16: ='Revenue Schedule'!IV31 -> 1.1627515e+11 | AP16: =AP11 -> 2246.2729 | AQ16: =AO16/AP16 -> 51763591
C17: Bus | F17: =F16 -> 952.639 | H17: =K17+N17+Q17+T17+W17+Z17+AC17+AF17+AI17+AL17+AO17 -> 1.1541257e+12 | I17: =I16 -> 952.639 | J17: =M17+P17+S17+V17+Y17+AB17+AE17+AH17+AK17+AN17+AQ17 -> 7.1796372e+08 | L17: =L16 -> 952.639 | M17: =K17/L17 -> 0 | N17: ='Revenue Schedule'!AE64 -> 15662809512 | O17: =O16 -> 952.639 | P17: =N17/O17 -> 16441495 | Q17: ='Revenue Schedule'!BD64 -> 3.28919e+10 | R17: =R16 -> 1047.9029 | S17: =Q17/R17 -> 31388309 | T17: ='Revenue Schedule'!CC64 -> 7.4206793e+10 | U17: =U16 -> 1152.6932 | V17: =T17/U17 -> 64376882 | W17: ='Revenue Schedule'!DB64 -> 1.0388951e+11 | X17: =X16 -> 1267.9625 | Y17: =W17/X17 -> 81934213 | Z17: ='Revenue Schedule'!EA64 -> 1.3635498e+11 | AA17: =AA16 -> 1394.7588 | AB17: =Z17/AA17 -> 97762413 | AC17: ='Revenue Schedule'!EZ64 -> 1.4317273e+11 | AD17: =AD16 -> 1534.2346 | AE17: =AC17/AD17 -> 93318667 | AF17: ='Revenue Schedule'!FY64 -> 1.5033137e+11 | AG17: =AG16 -> 1687.6581 | AH17: =AF17/AG17 -> 89076910 | AI17: ='Revenue Schedule'!GX64 -> 1.5784794e+11 | AJ17: =AJ16 -> 1856.4239 | AK17: =AI17/AJ17 -> 85027959 | AL17: ='Revenue Schedule'!HW64 -> 1.6574033e+11 | AM17: =AM16 -> 2042.0663 | AN17: =AL17/AM17 -> 81163052 | AO17: ='Revenue Schedule'!IV64 -> 1.7402735e+11 | AP17: =AP16 -> 2246.2729 | AQ17: =AO17/AP17 -> 77473822
C20: Fleets Disposal | AO20: 100000000000 | AP20: =AP17 -> 2246.2729 | AQ20: =AO20/AP20 -> 44518188
C22: TOTAL CASH INFLOWS | H22: =SUM(H8:H21) -> 2.0397755e+12 | J22: =SUM(J8:J21) -> #DIV/0! | K22: =SUM(K8:K21) -> 500000000 | M22: =SUM(M8:M21) -> #DIV/0! | N22: =SUM(N8:N21) -> 31098209512 | P22: =SUM(P8:P21) -> #DIV/0! | Q22: =SUM(Q8:Q21) -> 7.8964965e+10 | S22: =SUM(S8:S21) -> #DIV/0! | T22: =SUM(T8:T21) -> 1.8689038e+11 | V22: =SUM(V8:V21) -> #DIV/0! | W22: =SUM(W8:W21) -> 3.2992763e+11 | Y22: =SUM(Y8:Y21) -> #DIV/0! | Z22: =SUM(Z8:Z21) -> 5.047957e+11 | AB22: =SUM(AB8:AB21) -> 3.6192331e+08 | AC22: =SUM(AC8:AC21) -> 7.7143381e+11 | AE22: =SUM(AE8:AE21) -> 5.0281345e+08 | AF22: =SUM(AF8:AF21) -> 6.6701511e+11 | AH22: =SUM(AH8:AH21) -> 3.9523118e+08 | AI22: =SUM(AI8:AI21) -> 5.2163923e+11 | AK22: =SUM(AK8:AK21) -> 2.8099144e+08 | AL22: =SUM(AL8:AL21) -> 3.9721755e+11 | AN22: =SUM(AN8:AN21) -> 1.9451746e+08 | AO22: =SUM(AO8:AO21) -> 3.5433794e+11 | AQ22: =SUM(AQ8:AQ21) -> 1.5774483e+08
C24: CASH OUTFLOWS
C25: INVESTING ACTIVITIES
C28: Infrastructure
C30: Furnitures, Fittings and Equipment | D30: Actual | F30: =F17 -> 952.639 | G30: 1.1 | H30: =K30+N30+Q30+T30+W30+Z30+AC30+AF30+AI30+AL30+AO30 -> 55000000 | I30: =I17 -> 952.639 | J30: =M30+P30+S30+V30+Y30+AB30+AE30+AH30+AK30+AN30+AQ30 -> 57734.357 | K30: =CAPEX!C28 -> 55000000 | L30: =L17 -> 952.639 | M30: =K30/L30 -> 57734.357 | O30: =O17 -> 952.639 | P30: =N30/O30 -> 0 | Q30: =N30*$G30 -> 0 | R30: =R17 -> 1047.9029 | S30: =Q30/R30 -> 0 | T30: =Q30*$G30 -> 0 | U30: =U17 -> 1152.6932 | V30: =T30/U30 -> 0 | W30: =T30*$G30 -> 0 | X30: =X17 -> 1267.9625 | Y30: =W30/X30 -> 0 | Z30: =W30*$G30 -> 0 | AA30: =AA17 -> 1394.7588 | AB30: =Z30/AA30 -> 0 | AC30: =Z30*$G30 -> 0 | AD30: =AD17 -> 1534.2346 | AE30: =AC30/AD30 -> 0 | AF30: =AC30*$G30 -> 0 | AG30: =AG17 -> 1687.6581 | AH30: =AF30/AG30 -> 0 | AI30: =AF30*$G30 -> 0 | AJ30: =AJ17 -> 1856.4239 | AK30: =AI30/AJ30 -> 0 | AL30: =AI30*$G30 -> 0 | AM30: =AM17 -> 2042.0663 | AN30: =AL30/AM30 -> 0 | AO30: =AL30*$G30 -> 0 | AP30: =AP17 -> 2246.2729 | AQ30: =AO30/AP30 -> 0
C33: OPERATING ACTIVITIES
C35: Direct Cost
C37: Direct Labour/Wage Cost
